Workbook

Sheet CONFIGURATOR
B1: CONFIGURATION TOOL
B2: INSTRUCTIONS: WRITE IN THE YELLOW CELLS. THEN SEND THE RESULTS (GREEN CELLS) TO THE BOARD
B4: STEP 1: AFE SELECTION
B5: SELECT THE AFE PART AND NUMBER. CHECK THE METROLOGY REFERENCE GUIDE FOR THE OPTIONS AVAILABLE IN THE VERSION BEING USED.
B6: 2 x MCP3913. 12 channels and up to 11 powers are allowed
B8: STEP 2: CHANNEL CONFIGURATION
B9: CONFIGURE EACH CHANNEL AS A VOLTAGE OR CURRENT SOURCE, BY SELECTING THE SENSOR TYPE USED.
B10: CH ID | C10: 0 | D10: =1+C10 -> 1 | E10: =1+D10 -> 2 | F10: =1+E10 -> 3 | G10: =1+F10 -> 4 | H10: =1+G10 -> 5 | I10: =1+H10 -> 6 | J10: =1+I10 -> 7 | K10: =1+J10 -> 8 | ... AH10: =1+AG10 -> 31
B11: I/V SEL | C11: V | D11: V | E11: V | F11: I(CT) | G11: I(CT) | H11: I(CT) | I11: I(CT) | J11: I(CT) | K11: I(CT) | L11: I(CT) | M11: I(CT) | N11: I(CT) | O11: I(CT) | P11: I(CT) | Q11: I(CT) | R11: I(CT) | S11: I(CT) | T11: I(CT) | U11: I(CT) | V11: I(CT) | W11: I(CT) | X11: I(CT) | Y11: I(CT) | Z11: I(CT) | AA11: I(CT) | AB11: I(CT) | AC11: I(CT) | AD11: I(CT) | AE11: I(CT) | AF11: I(CT) | AG11: I(CT) | AH11: I(CT)
C12: =MATCH(C11, AUX_INTERNAL!$C$16:$C$19, 0)-1 -> 3 | D12: =MATCH(D11, AUX_INTERNAL!$C$16:$C$19, 0)-1 -> 3 | E12: =MATCH(E11, AUX_INTERNAL!$C$16:$C$19, 0)-1 -> 3 | F12: =MATCH(F11, AUX_INTERNAL!$C$16:$C$19, 0)-1 -> 0 | G12: =MATCH(G11, AUX_INTERNAL!$C$16:$C$19, 0)-1 -> 0 | H12: =MATCH(H11, AUX_INTERNAL!$C$16:$C$19, 0)-1 -> 0 | I12: =MATCH(I11, AUX_INTERNAL!$C$16:$C$19, 0)-1 -> 0 | J12: =MATCH(J11, AUX_INTERNAL!$C$16:$C$19, 0)-1 -> 0 | ... AH12: =MATCH(AH11, AUX_INTERNAL!$C$16:$C$19, 0)-1 -> 0
B14: STEP 3: POWER NUMBER
B15: SELECT THE NUMBER OF POWERS TO BE COMPUTED. THE NUMBER CAN EXCEED THE MAXIMUM LIMIT ESTABLISHED BY THE AFE SELECTION (STEP 1)
B16: 9 | D16: Max. Power Number | H16: {=INDIRECT(ADDRESS(ROW(AUX_INTERNAL!D4)+MATCH(B6,AUX_INTERNAL!C4:C11,0)-1,4,,,"AUX_INTERNAL"))-1} -> 11 | I16: Power number | L16: =IF(B16<H16,B16,H16) -> 9
B18: STEP 4: POWER MATRIX
B19: FOR EACH POWER, SELECT THE CHANNELS WITH THE CURRENT AND VOLTAGE INPUTS. BLUE LABEL SIGNALS THE LAST AVAILABLE POWER ID
B20: PW ID | C20: V CH | D20: I CH | E20: Meaning:
B21: 0 | C21: 0 | D21: 3 | E21: ="Power number " & B21& " is obtained from voltage channel " & C21& " and current channel " &D21 -> Power number 0 is obtained from voltage channel 0 and current channel 3
B22: =1+B21 -> 1 | C22: 0 | D22: 4 | E22: ="Power number " & B22& " is obtained from voltage channel " & C22& " and current channel " &D22 -> Power number 1 is obtained from voltage channel 0 and current channel 4
B23: =1+B22 -> 2 | C23: 0 | D23: 5 | E23: …
B24: =1+B23 -> 3 | C24: 1 | D24: 6 | E24: …
B25: =1+B24 -> 4 | C25: 1 | D25: 7 | E25: …
B26: =1+B25 -> 5 | C26: 1 | D26: 8 | E26: …
B27: =1+B26 -> 6 | C27: 2 | D27: 9 | E27: …
B28: =1+B27 -> 7 | C28: 2 | D28: 10 | E28: …
B29: =1+B28 -> 8 | C29: 2 | D29: 11 | E29: …
B30: =1+B29 -> 9 | C30: 0 | D30: 0 | E30: …
B31: =1+B30 -> 10 | C31: 0 | D31: 0 | E31: …
B32: =1+B31 -> 11 | C32: 0 | D32: 0 | E32: …
B33: =1+B32 -> 12 | C33: 0 | D33: 0 | E33: …
B34: =1+B33 -> 13 | C34: 0 | D34: 0 | E34: …
... B51: =1+B50 -> 30 | C51: 0 | D51: 0 | E51: …
B53: STEP 5: ADC INPUT CHANNEL CONVERSION FACTOR
B55: Resistor divider ratio | C55: 1651 | L55: VALUE(HEX) | O55: =MID(DEC2HEX(ROUND(C55*2^10,0),10),3,8) -> 0019CC00
R56: USE THIS VALUE FOR THE CURRENT CHANNELS ("Y" or "N", SELECT JUST ONE)
B57: CT Ratio | C57: 1000 | F57: Burden resistor | I57: 1.62 | J57: PGA | K57: 1 | L57: VALUE(HEX) | O57: =MID(DEC2HEX(ROUND(C57*2^10/2/I57/K57,0),10),3,8) -> 0004D291 | R57: Y | T57: =IF(R57="Y",O57,IF(R58="Y",O58,O59)) -> 0004D291
B58: Shunt resistor | C58: 100 | F58: PGA | I58: 8 | L58: VALUE(HEX) | O58: =MID(DEC2HEX(ROUND(2^10*1000000/C58/I58,0),10),3,8) -> 00138800 | R58: N
B59: Rogowski coil scale factor at 60Hz | C59: 500 | F59: PGA | I59: 4 | L59: VALUE(HEX) | O59: =MID(DEC2HEX(ROUND(2^10*1000000/C59/I59,0),10),3,8) -> 0007D000 | R59: N
B62: STEP 6: SEND THE GENERATED COMMANDS TO THE BOARD
B63: SEND THE COMMANDS TO THE BOARD. WHEN USING A SERIAL TERMINAL, SIMPLY COPY AND PASTE EACH ROW
B64: ="DCW[1](" & DEC2HEX((MATCH(B6,AUX_INTERNAL!C4:C11,0)-1)*2^28+L16*2^8) & ")" -> DCW[1](50000900)
...

Sheet CALIBRATION GUIDE
B1: PIC32CXMTx Calibration Spreadsheet
B3: STEP 1: CONFIGURE THE INPUT SOURCES AND SELECT THE CHANNELS TO BE CALIBRATED
B4: Type the values in the yellow cells:
B5: Test Current | C5: 30 | E5: Enable V-V Phase correction | F5: NO | G5: Enabled in future versions
B6: Test Voltage | C6: 220
B7: Meter Tester Freq | C7: 50
B8: Meter Tester I-V Phase | C8: 60
B9: Meter Tester V-V Phase | C9: 120
B12: CH ID | C12: V/I | D12: MAGNITUDE (V/I) | E12: CALIBRATE (Y/N)
B13: 0 | C13: =CONFIGURATOR!C11 -> V | D13: =IF(C13="V",$C$6,$C$5) -> 220 | E13: Y
B14: 1 | C14: =CONFIGURATOR!D11 -> V | D14: =IF(C14="V",$C$6,$C$5) -> 220 | E14: Y
B15: 2 | C15: =CONFIGURATOR!E11 -> V | D15: =IF(C15="V",$C$6,$C$5) -> 220 | E15: Y
B16: 3 | C16: =CONFIGURATOR!F11 -> I(CT) | D16: =IF(C16="V",$C$6,$C$5) -> 30 | E16: Y
B17: 4 | C17: =CONFIGURATOR!G11 -> I(CT) | D17: =IF(C17="V",$C$6,$C$5) -> 30 | E17: Y
B18: 5 | C18: =CONFIGURATOR!H11 -> I(CT) | D18: =IF(C18="V",$C$6,$C$5) -> 30 | E18: Y
B19: 6 | C19: =CONFIGURATOR!I11 -> I(CT) | D19: =IF(C19="V",$C$6,$C$5) -> 30 | E19: N
B20: 7 | C20: =CONFIGURATOR!J11 -> I(CT) | D20: =IF(C20="V",$C$6,$C$5) -> 30 | E20: N
B21: 8 | C21: =CONFIGURATOR!K11 -> I(CT) | D21: =IF(C21="V",$C$6,$C$5) -> 30 | E21: N
B22: 9 | C22: =CONFIGURATOR!L11 -> I(CT) | D22: =IF(C22="V",$C$6,$C$5) -> 30 | E22: N
B23: 10 | C23: =CONFIGURATOR!M11 -> I(CT) | D23: =IF(C23="V",$C$6,$C$5) -> 30 | E23: N
B24: 11 | C24: =CONFIGURATOR!N11 -> I(CT) | D24: =IF(C24="V",$C$6,$C$5) -> 30 | E24: N
B25: 12 | C25: =CONFIGURATOR!O11 -> I(CT) | D25: =IF(C25="V",$C$6,$C$5) -> 30 | E25: N
B26: 13 | C26: =CONFIGURATOR!P11 -> I(CT) | D26: =IF(C26="V",$C$6,$C$5) -> 30 | E26: N
B27: 14 | C27: =CONFIGURATOR!Q11 -> I(CT) | D27: =IF(C27="V",$C$6,$C$5) -> 30 | E27: N
B28: 15 | C28: =CONFIGURATOR!R11 -> I(CT) | D28: =IF(C28="V",$C$6,$C$5) -> 30 | E28: N
B29: 16 | C29: =CONFIGURATOR!S11 -> I(CT) | D29: =IF(C29="V",$C$6,$C$5) -> 30 | E29: N
B30: 17 | C30: =CONFIGURATOR!T11 -> I(CT) | D30: =IF(C30="V",$C$6,$C$5) -> 30 | E30: N
B31: 18 | C31: =CONFIGURATOR!U11 -> I(CT) | D31: =IF(C31="V",$C$6,$C$5) -> 30 | E31: N
B32: 19 | C32: =CONFIGURATOR!V11 -> I(CT) | D32: =IF(C32="V",$C$6,$C$5) -> 30 | E32: N
B33: 20 | C33: =CONFIGURATOR!W11 -> I(CT) | D33: =IF(C33="V",$C$6,$C$5) -> 30 | E33: N
B34: 21 | C34: =CONFIGURATOR!X11 -> I(CT) | D34: =IF(C34="V",$C$6,$C$5) -> 30 | E34: N
B35: 22 | C35: =CONFIGURATOR!Y11 -> I(CT) | D35: =IF(C35="V",$C$6,$C$5) -> 30 | E35: N
B36: 23 | C36: =CONFIGURATOR!Z11 -> I(CT) | D36: =IF(C36="V",$C$6,$C$5) -> 30 | E36: N
B37: 24 | C37: =CONFIGURATOR!AA11 -> I(CT) | D37: =IF(C37="V",$C$6,$C$5) -> 30 | E37: N
B38: 25 | C38: =CONFIGURATOR!AB11 -> I(CT) | D38: =IF(C38="V",$C$6,$C$5) -> 30 | E38: N
B39: 26 | C39: =CONFIGURATOR!AC11 -> I(CT) | D39: =IF(C39="V",$C$6,$C$5) -> 30 | E39: N
B40: 27 | C40: =CONFIGURATOR!AD11 -> I(CT) | D40: =IF(C40="V",$C$6,$C$5) -> 30 | E40: N
B41: 28 | C41: =CONFIGURATOR!AE11 -> I(CT) | D41: =IF(C41="V",$C$6,$C$5) -> 30 | E41: N
B42: 29 | C42: =CONFIGURATOR!AF11 -> I(CT) | D42: =IF(C42="V",$C$6,$C$5) -> 30 | E42: N
B43: 30 | C43: =CONFIGURATOR!AG11 -> I(CT) | D43: =IF(C43="V",$C$6,$C$5) -> 30 | E43: N
...

Sheet TOOLS
B1: SAM4CMx / PIC32CXMTx TOOLS
B2: CALCULATORS
B3: In the yellow cells, type the values to be configured | H3: Parameters used in the cauculations
B4: PARAMETER | C4: NEW VALUE | D4: DEFAULT VALUE | E4: NEEDED COMMANDS | F4: NOTES | H4: PARAMETER | I4: VALUE
B5: Meter constant (P) | C5: 3200 | D5: 3200 | E5: ="DCW[32]("& DEC2HEX(ROUND(1000*2^24/C5,0)) &")" -> DCW[32](500000) | F5: Check if the pulse width allows to reach the expected max pulse rate (max power applied) | H5: Frequency | I5: 50
B6: Meter constant (Q) | C6: 3200 | D6: 3200 | E6: ="DCW[33]("& DEC2HEX(ROUND(1000*2^24/C6,0)) &")" -> DCW[33](500000) | H6: K_x (Current) | I6: =HEX2DEC("9A523")/2^10 -> 617.28418
B7: Meter constant (I^2) | C7: 3200 | D7: 3200 | E7: ="DCW[34]("& DEC2HEX(ROUND(1000*2^24/C7,0)) &")" -> DCW[34](500000) | H7: K_x (Voltage) | I7: =HEX2DEC("19CC00")/2^10 -> 1651
B8: Creep threshold (P) | C8: 11 | D8: 0 | E8: ="DCW[35]("&MID(DEC2HEX(ROUND(TOOLS!C8/I5/3600*2^30,0),10),3,8) &")" -> DCW[35](00010052) | F8: Enable/Disable with Feature Control 1 Register
B9: Creep threshold (Q) | C9: 11 | D9: 0 | E9: ="DCW[36]("&MID(DEC2HEX(ROUND(TOOLS!C9/I5/3600*2^30,0),10),3,8) &")" -> DCW[36](00010052)
B10: Creep threshold (I) | C10: 10 | D10: 0 | E10: ="DCW[37]("&MID(DEC2HEX(ROUND(TOOLS!C10/I6*2^20,0),10),3,8) &")" -> DCW[37](0000425B)
B11: Power offset (P_x) | C11: -5 | D11: 0 | E11: ="DCW[218](" & MID(DEC2HEX(-ROUND(C11*2^40/(I6*I7),0),10),3,8) &")" -> DCW[218](00524F9B) | F11: Enable/Disable with power offset control register
B12: Power offset (Q_x) | C12: -5 | D12: 0 | E12: ="DCW[250](" & MID(DEC2HEX(-ROUND(C12*2^40/(I6*I7),0),10),3,8) &")" -> DCW[250](00524F9B)
B13: Global P offset | C13: 0.05 | D13: 0 | E13: ="DCW[40](" & MID(DEC2HEX(-ROUND(C13*2^30/180000,0),10),3,8) &")" -> DCW[40](FFFFFED6)
B14: Global Q offset | C14: -0.05 | D14: 0 | E14: ="DCW[41](" & MID(DEC2HEX(-ROUND(C14*2^30/180000,0),10),3,8) &")" -> DCW[41](0000012A)
B17: PULSE RATE CALCULATOR (USEFUL TO CONFIGURE THE PULSE WIDTH)
B18: Enter the values in the yellow cells. The blue cell shows the result.
B19: METER CONSTANT | C19: APPLIED POWER | D19: PULSE RATE
B20: 3200 | C20: 18 | D20: =B20*C20/3600 -> 16

Sheet Version control
B2: Version | C2: Date | D2: Changes
B3: 6 | C3: 45455 | D3: Preliminary version for multichannel metrology library
B4: 5 | C4: 45176 | D4: "Tools" worksheet added
B5: 4 | C5: 44853 | D5: This version supports the new features of the neutral current measuremnts. It requires SAM4CM metrology library 2.0.0B or newer; or PIC32CXMTx 3.0.0A or newer Valid for SAM4CM and PIC32CX
B6: 3.1 | C6: 44771 | D6: Fixed issue calculating CAL_PH_Ix when "Meter Test Freq" (Q5) is different from 60Hz. Calculations of P_x and Q_X quantities fixed (a constant of "4000" was used instead of status register "N")
B7: 3 | C7: 44614 | D7: Initial edition

Sheet CMD GENERATOR
B1: MCP391x TOOLS - WRITE JUST IN THE YELLOW CELLS; COMMANDS IN GREEN
AY2: AFE SELECTION | BD2: CHANNEL TYPE
B3: POWER NUMBER | I3: Channel type | AY3: 0 - 1xMCP3914 | BD3: I(CT) | BE3: 0
B4: 9 | H4: CH index | I4: 0 | J4: =1+I4 -> 1 | K4: =1+J4 -> 2 | L4: =1+K4 -> 3 | M4: =1+L4 -> 4 | N4: =1+M4 -> 5 | O4: =1+N4 -> 6 | P4: =1+O4 -> 7 | Q4: =1+P4 -> 8 | ... AN4: =1+AM4 -> 31 | AY4: 1 - 2xMCP3914 | BD4: I(RC) | BE4: 1
H5: SEL I/V | I5: V | J5: V | K5: V | L5: I(CT) | M5: I(CT) | N5: I(CT) | O5: I(CT) | P5: V | Q5: I(CT) | R5: V | S5: I(CT) | T5: V | U5: I(CT) | V5: I(CT) | W5: I(CT) | X5: I(CT) | Y5: I(CT) | Z5: I(CT) | AA5: I(CT) | AB5: I(CT) | AC5: I(CT) | AD5: I(CT) | AE5: I(CT) | AF5: I(CT) | AG5: I(CT) | AH5: I(CT) | AI5: I(CT) | AJ5: I(CT) | AK5: I(CT) | AL5: I(CT) | AM5: I(CT) | AN5: I(CT) | AY5: 2 - 3xMCP3914 | BD5: I(SH) | BE5: 2
H6: Number | I6: =MATCH(I5, $BD$3:$BD$6, 0)-1 -> 3 | J6: =MATCH(J5, $BD$3:$BD$6, 0)-1 -> 3 | K6: =MATCH(K5, $BD$3:$BD$6, 0)-1 -> 3 | L6: =MATCH(L5, $BD$3:$BD$6, 0)-1 -> 0 | M6: =MATCH(M5, $BD$3:$BD$6, 0)-1 -> 0 | N6: =MATCH(N5, $BD$3:$BD$6, 0)-1 -> 0 | O6: =MATCH(O5, $BD$3:$BD$6, 0)-1 -> 0 | P6: =MATCH(P5, $BD$3:$BD$6, 0)-1 -> 3 | ... AN6: =MATCH(AN5, $BD$3:$BD$6, 0)-1 -> 0 | AY6: 3 - 4xMCP3914 | BD6: V | BE6: 3
AB7: V_Default | AE7: 19CC00 | AH7: I_default | AK7: 9A523 | AY7: 4 - 1xMCP3913
H8: ="DCW[21]("&Q8&")" -> DCW[21](00CCC03F) | O8: Param | Q8: =DEC2HEX(I6*2^0+J6*2^2+K6*2^4+L6*2^6+M6*2^8+N6*2^10+O6*2^12+P6*2^14+Q6*2^16+R6*2^18+S6*2^20+T6*2^22+U6*2^24+V6*2^26+W6*2^28+X6*2^30,8) -> 00CCC03F | AB8: K_CH_x (K_CH must be also changed, in order the synthezizer to produce the proper magnitude) | AY8: 5 - 2xMCP3913
H9: ="DCW[22]("&Q9&")" -> DCW[22](00000000) | O9: Param | Q9: =DEC2HEX(Y6*2^0+Z6*2^2+AA6*2^4+AB6*2^6+AC6*2^8+AD6*2^10+AE6*2^12+AF6*2^14+AG6*2^16+AH6*2^18+AI6*2^20+AJ6*2^22+AK6*2^24+AL6*2^26+AM6*2^28+AN6*2^30,8) -> 00000000 | AA9: Offset | AB9: x | AC9: Reg | AD9: V/I | AE9: CMD_V | AH9: CMD | AM9: COMBINED CMD | AY9: 6 - 3xMCP3913
AA10: 106 | AB10: 0 | AC10: =AB10+$AA$10 -> 106 | AD10: =IF($I$6=3, "V", "I") -> V | AE10: =IF(AD10="V",$AE$7,$AK$7) -> 19CC00 | AH10: ="DCW["&AC10&"]("&AE10&")" -> DCW[106](19CC00) | AM10: 32 CHANNELS | AY10: 7 - 4xMCP3913
AB11: =1+AB10 -> 1 | AC11: =AB11+$AA$10 -> 107 | AD11: =IF($J$6=3, "V", "I") -> V | AE11: =IF(AD11="V",$AE$7,$AK$7) -> 19CC00 | AH11: ="DCW["&AC11&"]("&AE11&")" -> DCW[107](19CC00)
AB12: =1+AB11 -> 2 | AC12: =AB12+$AA$10 -> 108 | AD12: =IF($K$6=3, "V", "I") -> V | AE12: =IF(AD12="V",$AE$7,$AK$7) -> 19CC00 | AH12: ="DCW["&AC12&"]("&AE12&")" -> DCW[108](19CC00) | AM12: 16 CHANNELS | AY12: SYNTHESIZER
B13: PH number | C13: V source | D13: I source | E13: Ctrl reg | F13: Param | G13: COMMAND | H13: TOTAL CMD - PHASE SOURCE REGISTERS | AB13: =1+AB12 -> 3 | AC13: =AB13+$AA$10 -> 109 | AD13: =IF($L$6=3, "V", "I") -> I | AE13: =IF(AD13="V",$AE$7,$AK$7) -> 9A523 | AH13: ="DCW["&AC13&"]("&AE13&")" -> DCW[109](9A523) | AM13: ="DCM("&AC10&":"&AE10&";" &AC11&":"&AE11&";" &AC12&":"&AE12&";" &AC13&":"&AE13&";" &AC14&":"&AE14&";" &AC15&":"&AE15&";" &AC16&":"&AE16&";" &AC17&":"&AE17&";" &AC18&":"&AE18&";" &AC19&":"&AE19&";" &AC20&":"&AE20&";" &AC21&":"&AE21&";" &AC22&":"&AE22&";" &AC23&":"&AE23&";" &AC24&":"&AE24&";" &AC25&":"&AE25 &")" -> DCM(106:19CC00;107:19CC00;108:19CC00;109:9A523;110:9A523;111:9A523;112:9A523;113:19CC00;114:9A523;115:19CC00;116:9A523;117:19CC00;118:9A523;119:9A523;120:9A523;121:9A523) | AY13: 220v | AZ13: 202334585
B14: 0 | C14: 0 | D14: 1 | E14: 4 | F14: =DEC2HEX(C14+D14*256) -> 100 | G14: ="DCW["&E14&"]("&F14&")" -> DCW[4](100) | H14: =IF(B14=($B$4-1),"DCM("&E14&":"&F14&") """) -> FALSE | AB14: =1+AB13 -> 4 | AC14: =AB14+$AA$10 -> 110 | AD14: =IF($M$6=3, "V", "I") -> I | AE14: =IF(AD14="V",$AE$7,$AK$7) -> 9A523 | AH14: ="DCW["&AC14&"]("&AE14&")" -> DCW[110](9A523) | AM14: 12 CHANNELS | AY14: 100A | AZ14: 245986054
B15: =1+B14 -> 1 | C15: 0 | D15: 2 | E15: 4 | F15: =DEC2HEX(C14+D14*256+C15*2^16+D15*2^24) -> 2000100 | G15: ="DCW["&E15&"]("&F15&")" -> DCW[4](2000100) | H15: =IF(B15=($B$4-1),"DCM("&E15&":"&F15&")") -> FALSE | AB15: =1+AB14 -> 5 | AC15: =AB15+$AA$10 -> 111 | AD15: =IF($N$6=3, "V", "I") -> I | AE15: =IF(AD15="V",$AE$7,$AK$7) -> 9A523 | AH15: ="DCW["&AC15&"]("&AE15&")" -> DCW[111](9A523) | AM15: ="DCM("&AC10&":"&AE10&";" &AC11&":"&AE11&";" &AC12&":"&AE12&";" &AC13&":"&AE13&";" &AC14&":"&AE14&";" &AC15&":"&AE15&";" &AC16&":"&AE16&";" &AC17&":"&AE17&";" &AC18&":"&AE18&";" &AC19&":"&AE19&";" &AC20&":"&AE20&";" &AC21&":"&AE21 &")" -> DCM(106:19CC00;107:19CC00;108:19CC00;109:9A523;110:9A523;111:9A523;112:9A523;113:19CC00;114:9A523;115:19CC00;116:9A523;117:19CC00)
B16: =1+B15 -> 2 | C16: 0 | D16: 3 | E16: 5 | F16: =DEC2HEX(C16+D16*256) -> 300 | G16: ="DCW["&E16&"]("&F16&")" -> DCW[5](300) | H16: =IF(B16=($B$4-1),"DCM("&E15&":"&F15&"; "&E16&":"&F16&")") -> FALSE | AB16: =1+AB15 -> 6 | AC16: =AB16+$AA$10 -> 112 | AD16: =IF($O$6=3, "V", "I") -> I | AE16: =IF(AD16="V",$AE$7,$AK$7) -> 9A523 | AH16: ="DCW["&AC16&"]("&AE16&")" -> DCW[112](9A523) | AM16: 8 CHANNELS
B17: =1+B16 -> 3 | C17: 0 | D17: 4 | E17: 5 | F17: =DEC2HEX(C16+D16*256+C17*2^16+D17*2^24) -> 4000300 | G17: ="DCW["&E17&"]("&F17&")" -> DCW[5](4000300) | H17: =IF(B17=($B$4-1),"DCM("&E15&":"&F15&"; "&E17&":"&F17&")") -> FALSE | AB17: =1+AB16 -> 7 | AC17: =AB17+$AA$10 -> 113 | AD17: =IF($P$6=3, "V", "I") -> V | AE17: =IF(AD17="V",$AE$7,$AK$7) -> 19CC00 | AH17: ="DCW["&AC17&"]("&AE17&")" -> DCW[113](19CC00) | AM17: ="DCM("&AC10&":"&AE10&";" &AC11&":"&AE11&";" &AC12&":"&AE12&";" &AC13&":"&AE13&";" &AC14&":"&AE14&";" &AC15&":"&AE15&";" &AC16&":"&AE16&";" &AC17&":"&AE17 &")" -> DCM(106:19CC00;107:19CC00;108:19CC00;109:9A523;110:9A523;111:9A523;112:9A523;113:19CC00)
B18: =1+B17 -> 4 | C18: 0 | D18: 5 | E18: 6 | F18: =DEC2HEX(C18+D18*256) -> 500 | G18: ="DCW["&E18&"]("&F18&")" -> DCW[6](500) | H18: =IF(B18=($B$4-1),"DCM("&E15&":"&F15&"; "&E17&":"&F17&"; "&E18&":"&F18&")") -> FALSE | AB18: =1+AB17 -> 8 | AC18: =AB18+$AA$10 -> 114 | AD18: =IF($Q$6=3, "V", "I") -> I | AE18: =IF(AD18="V",$AE$7,$AK$7) -> 9A523 | AH18: ="DCW["&AC18&"]("&AE18&")" -> DCW[114](9A523)
B19: =1+B18 -> 5 | C19: 6 | D19: 7 | E19: 6 | F19: =DEC2HEX(C18+D18*256+C19*2^16+D19*2^24) -> 7060500 | G19: ="DCW["&E19&"]("&F19&")" -> DCW[6](7060500) | H19: =IF(B19=($B$4-1),"DCM("&E15&":"&F15&"; "&E17&":"&F17&"; "&E19&":"&F19&")") -> FALSE | AB19: =1+AB18 -> 9 | AC19: =AB19+$AA$10 -> 115 | AD19: =IF($R$6=3, "V", "I") -> V | AE19: =IF(AD19="V",$AE$7,$AK$7) -> 19CC00 | AH19: ="DCW["&AC19&"]("&AE19&")" -> DCW[115](19CC00)
B20: =1+B19 -> 6 | C20: 6 | D20: 8 | E20: 7 | F20: =DEC2HEX(C20+D20*256) -> 806 | G20: ="DCW["&E20&"]("&F20&")" -> DCW[7](806) | H20: =IF(B20=($B$4-1),"DCM("&E15&":"&F15&"; "&E17&":"&F17&"; "&E19&":"&F19&"; "&E20&":"&F20&")") -> FALSE | AB20: =1+AB19 -> 10 | AC20: =AB20+$AA$10 -> 116 | AD20: =IF($S$6=3, "V", "I") -> I | AE20: =IF(AD20="V",$AE$7,$AK$7) -> 9A523 | AH20: ="DCW["&AC20&"]("&AE20&")" -> DCW[116](9A523)
B21: =1+B20 -> 7 | C21: 6 | D21: 9 | E21: 7 | F21: =DEC2HEX(C20+D20*256+C21*2^16+D21*2^24) -> 9060806 | G21: ="DCW["&E21&"]("&F21&")" -> DCW[7](9060806) | H21: =IF(B21=($B$4-1),"DCM("&E15&":"&F15&"; "&E17&":"&F17&"; "&E19&":"&F19&";"&E21&":"&F21&")") -> FALSE | AB21: =1+AB20 -> 11 | AC21: =AB21+$AA$10 -> 117 | AD21: =IF($T$6=3, "V", "I") -> V | AE21: =IF(AD21="V",$AE$7,$AK$7) -> 19CC00 | AH21: ="DCW["&AC21&"]("&AE21&")" -> DCW[117](19CC00)
B22: =1+B21 -> 8 | C22: 6 | D22: 10 | E22: 8 | F22: =DEC2HEX(C22+D22*256) -> A06 | G22: ="DCW["&E22&"]("&F22&")" -> DCW[8](A06) | H22: =IF(B22=($B$4-1),"DCM("&E15&":"&F15&"; "&E17&":"&F17&"; "&E19&":"&F19&"; "&E21&":"&F21&"; "&E22&":"&F22&")") -> DCM(4:2000100; 5:4000300; 6:7060500; 7:9060806; 8:A06) | AB22: =1+AB21 -> 12 | AC22: =AB22+$AA$10 -> 118 | AD22: =IF($U$6=3, "V", "I") -> I | AE22: =IF(AD22="V",$AE$7,$AK$7) -> 9A523 | AH22: ="DCW["&AC22&"]("&AE22&")" -> DCW[118](9A523)
B23: =1+B22 -> 9 | C23: 11 | D23: 12 | E23: 8 | F23: =DEC2HEX(C22+D22*256+C23*2^16+D23*2^24) -> C0B0A06 | G23: ="DCW["&E23&"]("&F23&")" -> DCW[8](C0B0A06) | H23: =IF(B23=($B$4-1),"DCM("&E15&":"&F15&"; "&E17&":"&F17&"; "&E19&":"&F19&"; "&E21&":"&F21&"; "&E23&":"&F23&")") -> FALSE | AB23: =1+AB22 -> 13 | AC23: =AB23+$AA$10 -> 119 | AD23: =IF($V$6=3, "V", "I") -> I | AE23: =IF(AD23="V",$AE$7,$AK$7) -> 9A523 | AH23: ="DCW["&AC23&"]("&AE23&")" -> DCW[119](9A523)
B24: =1+B23 -> 10 | C24: 11 | D24: 13 | E24: 9 | F24: =DEC2HEX(C24+D24*256) -> D0B | G24: ="DCW["&E24&"]("&F24&")" -> DCW[9](D0B) | H24: =IF(B24=($B$4-1),"DCM("&E15&":"&F15&"; "&E17&":"&F17&"; "&E19&":"&F19&"; "&E21&":"&F21&"; "&E23&":"&F23&"; "&E24&":"&F24&")") -> FALSE | AB24: =1+AB23 -> 14 | AC24: =AB24+$AA$10 -> 120 | AD24: =IF($W$6=3, "V", "I") -> I | AE24: =IF(AD24="V",$AE$7,$AK$7) -> 9A523 | AH24: ="DCW["&AC24&"]("&AE24&")" -> DCW[120](9A523)
B25: =1+B24 -> 11 | C25: 11 | D25: 14 | E25: 9 | F25: =DEC2HEX(C24+D24*256+C25*2^16+D25*2^24) -> E0B0D0B | G25: ="DCW["&E25&"]("&F25&")" -> DCW[9](E0B0D0B) | H25: =IF(B25=($B$4-1),"DCM("&E15&":"&F15&"; "&E17&":"&F17&"; "&E19&":"&F19&"; "&E21&":"&F21&"; "&E23&":"&F23&"; "&E25&":"&F25&")") -> FALSE | AB25: =1+AB24 -> 15 | AC25: =AB25+$AA$10 -> 121 | AD25: =IF($X$6=3, "V", "I") -> I | AE25: =IF(AD25="V",$AE$7,$AK$7) -> 9A523 | AH25: ="DCW["&AC25&"]("&AE25&")" -> DCW[121](9A523)
B26: =1+B25 -> 12 | C26: 11 | D26: 15 | E26: 10 | F26: =DEC2HEX(C26+D26*256) -> F0B | G26: ="DCW["&E26&"]("&F26&")" -> DCW[10](F0B) | H26: =IF(B26=($B$4-1),"DCM("&E15&":"&F15&"; "&E17&":"&F17&"; "&E19&":"&F19&"; "&E21&":"&F21&"; "&E23&":"&F23&"; "&E25&":"&F25&"; "&E26&":"&F26&")") -> FALSE | AB26: =1+AB25 -> 16 | AC26: =AB26+$AA$10 -> 122 | AD26: =IF($Y$6=3, "V", "I") -> I | AE26: =IF(AD26="V",$AE$7,$AK$7) -> 9A523 | AH26: ="DCW["&AC26&"]("&AE26&")" -> DCW[122](9A523)
B27: =1+B26 -> 13 | C27: 0 | D27: 0 | E27: 10 | F27: =DEC2HEX(C26+D26*256+C27*2^16+D27*2^24) -> F0B | G27: ="DCW["&E27&"]("&F27&")" -> DCW[10](F0B) | H27: =IF(B27=($B$4-1),"DCM("&E15&":"&F15&"; "&E17&":"&F17&"; "&E19&":"&F19&"; "&E21&":"&F21&"; "&E23&":"&F23&"; "&E25&":"&F25&"; "&E27&":"&F27&")") -> FALSE | AB27: =1+AB26 -> 17 | AC27: =AB27+$AA$10 -> 123 | AD27: =IF($Z$6=3, "V", "I") -> I | AE27: =IF(AD27="V",$AE$7,$AK$7) -> 9A523 | AH27: ="DCW["&AC27&"]("&AE27&")" -> DCW[123](9A523)
B28: =1+B27 -> 14 | C28: 5 | D28: 15 | E28: 11 | F28: =DEC2HEX(C28+D28*256) -> F05 | G28: ="DCW["&E28&"]("&F28&")" -> DCW[11](F05) | H28: =IF(B28=($B$4-1),"DCM("&E15&":"&F15&"; "&E17&":"&F17&"; "&E19&":"&F19&"; "&E21&":"&F21&"; "&E23&":"&F23&"; "&E25&":"&F25&"; "&E27&":"&F27&"; "&E28&":"&F28&")") -> FALSE | AB28: =1+AB27 -> 18 | AC28: =AB28+$AA$10 -> 124 | AD28: =IF($AA$6=3, "V", "I") -> I | AE28: =IF(AD28="V",$AE$7,$AK$7) -> 9A523 | AH28: ="DCW["&AC28&"]("&AE28&")" -> DCW[124](9A523)
B29: =1+B28 -> 15 | C29: 5 | D29: 16 | E29: 11 | F29: =DEC2HEX(C28+D28*256+C29*2^16+D29*2^24) -> 10050F05 | G29: ="DCW["&E29&"]("&F29&")" -> DCW[11](10050F05) | H29: =IF(B29=($B$4-1),"DCM("&E15&":"&F15&"; "&E17&":"&F17&"; "&E19&":"&F19&"; "&E21&":"&F21&"; "&E23&":"&F23&"; "&E25&":"&F25&"; "&E27&":"&F27&"; "&E29&":"&F29&")") -> FALSE | AB29: =1+AB28 -> 19 | AC29: =AB29+$AA$10 -> 125 | AD29: =IF($AB$6=3, "V", "I") -> I | AE29: =IF(AD29="V",$AE$7,$AK$7) -> 9A523 | AH29: ="DCW["&AC29&"]("&AE29&")" -> DCW[125](9A523)
B30: =1+B29 -> 16 | C30: 5 | D30: 17 | E30: 12 | F30: =DEC2HEX(C30+D30*256) -> 1105 | G30: ="DCW["&E30&"]("&F30&")" -> DCW[12](1105) | H30: =IF(B30=($B$4-1),"DCM("&E15&":"&F15&"; "&E17&":"&F17&"; "&E19&":"&F19&";"&E21&":"&F21&"; "&E23&":"&F23&"; "&E25&":"&F25&"; "&E27&":"&F27&"; "&E29&":"&F29&"; "&E30&":"&F30&")") -> FALSE | AB30: =1+AB29 -> 20 | AC30: =AB30+$AA$10 -> 126 | AD30: =IF($AC$6=3, "V", "I") -> I | AE30: =IF(AD30="V",$AE$7,$AK$7) -> 9A523 | AH30: ="DCW["&AC30&"]("&AE30&")" -> DCW[126](9A523)
B31: =1+B30 -> 17 | C31: 11 | D31: 18 | E31: 12 | F31: =DEC2HEX(C30+D30*256+C31*2^16+D31*2^24) -> 120B1105 | G31: ="DCW["&E31&"]("&F31&")" -> DCW[12](120B1105) | H31: =IF(B11=($B$4-1),"DCM("&E15&":"&F15&"; "&E17&":"&F17&"; "&E19&":"&F19&"; "&E21&":"&F21&"; "&E23&":"&F23&"; "&E25&":"&F25&"; "&E27&":"&F27&"; "&E29&":"&F29&"; "&E31&":"&F31&")") -> FALSE | AB31: =1+AB30 -> 21 | AC31: =AB31+$AA$10 -> 127 | AD31: =IF($AD$6=3, "V", "I") -> I | AE31: =IF(AD31="V",$AE$7,$AK$7) -> 9A523 | AH31: ="DCW["&AC31&"]("&AE31&")" -> DCW[127](9A523)
B32: =1+B31 -> 18 | C32: 11 | D32: 19 | E32: 13 | F32: =DEC2HEX(C32+D32*256) -> 130B | G32: ="DCW["&E32&"]("&F32&")" -> DCW[13](130B) | H32: =IF(B32=($B$4-1),"DCM("&E15&":"&F15&"; "&E17&":"&F17&"; "&E19&":"&F19&"; "&E21&":"&F21&"; "&E23&":"&F23&"; "&E25&":"&F25&"; "&E27&":"&F27&"; "&E29&":"&F29&"; "&E31&":"&F31&"; "&E32&":"&F32&")") -> FALSE | AB32: =1+AB31 -> 22 | AC32: =AB32+$AA$10 -> 128 | AD32: =IF($AE$6=3, "V", "I") -> I | AE32: =IF(AD32="V",$AE$7,$AK$7) -> 9A523 | AH32: ="DCW["&AC32&"]("&AE32&")" -> DCW[128](9A523)
B33: =1+B32 -> 19 | C33: 11 | D33: 20 | E33: 13 | F33: =DEC2HEX(C32+D32*256+C33*2^16+D33*2^24) -> 140B130B | G33: ="DCW["&E33&"]("&F33&")" -> DCW[13](140B130B) | H33: =IF(B33=($B$4-1),"DCM("&E15&":"&F15&"; "&E17&":"&F17&"; "&E19&":"&F19&"; "&E21&":"&F21&"; "&E23&":"&F23&"; "&E25&":"&F25&"; "&E27&":"&F27&"; "&E29&":"&F29&"; "&E31&":"&F31&"; "&E33&":"&F33&")") -> FALSE | AB33: =1+AB32 -> 23 | AC33: =AB33+$AA$10 -> 129 | AD33: =IF($AF$6=3, "V", "I") -> I | AE33: =IF(AD33="V",$AE$7,$AK$7) -> 9A523 | AH33: ="DCW["&AC33&"]("&AE33&")" -> DCW[129](9A523)
B34: =1+B33 -> 20 | C34: 11 | D34: 21 | E34: 14 | F34: =DEC2HEX(C34+D34*256) -> 150B | G34: ="DCW["&E34&"]("&F34&")" -> DCW[14](150B) | H34: =IF(B34=($B$4-1),"DCM("&E15&":"&F15&"; "&E17&":"&F17&"; "&E19&":"&F19&"; "&E21&":"&F21&"; "&E23&":"&F23&"; "&E25&":"&F25&"; "&E27&":"&F27&"; "&E29&":"&F29&"; "&E31&":"&F31&"; "&E33&":"&F33&"; "&E34&":"&F34&")") -> FALSE | AB34: =1+AB33 -> 24 | AC34: =AB34+$AA$10 -> 130 | AD34: =IF($AG$6=3, "V", "I") -> I | AE34: =IF(AD34="V",$AE$7,$AK$7) -> 9A523 | AH34: ="DCW["&AC34&"]("&AE34&")" -> DCW[130](9A523)
B35: =1+B34 -> 21 | C35: 11 | D35: 22 | E35: 14 | F35: =DEC2HEX(C34+D34*256+C35*2^16+D35*2^24) -> 160B150B | G35: ="DCW["&E35&"]("&F35&")" -> DCW[14](160B150B) | H35: =IF(B35=($B$4-1),"DCM("&E15&":"&F15&"; "&E17&":"&F17&"; "&E19&":"&F19&"; "&E21&":"&F21&"; "&E23&":"&F23&"; "&E25&":"&F25&"; "&E27&":"&F27&"; "&E29&":"&F29&"; "&E31&":"&F31&"; "&E33&":"&F33&"; "&E35&":"&F35&")") -> FALSE | AB35: =1+AB34 -> 25 | AC35: =AB35+$AA$10 -> 131 | AD35: =IF($AH$6=3, "V", "I") -> I | AE35: =IF(AD35="V",$AE$7,$AK$7) -> 9A523 | AH35: ="DCW["&AC35&"]("&AE35&")" -> DCW[131](9A523)
B36: =1+B35 -> 22 | C36: 11 | D36: 23 | E36: 15 | F36: =DEC2HEX(C36+D36*256) -> 170B | G36: ="DCW["&E36&"]("&F36&")" -> DCW[15](170B) | H36: =IF(B36=($B$4-1),"DCM("&E15&":"&F15&"; "&E17&":"&F17&"; "&E19&":"&F19&"; "&E21&":"&F21&"; "&E23&":"&F23&"; "&E25&":"&F25&"; "&E27&":"&F27&"; "&E29&":"&F29&"; "&E31&":"&F31&"; "&E33&":"&F33&"; "&E35&":"&F35&"; "&E36&":"&F36&")") -> FALSE | AB36: =1+AB35 -> 26 | AC36: =AB36+$AA$10 -> 132 | AD36: =IF($AI$6=3, "V", "I") -> I | AE36: =IF(AD36="V",$AE$7,$AK$7) -> 9A523 | AH36: ="DCW["&AC36&"]("&AE36&")" -> DCW[132](9A523)
B37: =1+B36 -> 23 | C37: 11 | D37: 24 | E37: 15 | F37: =DEC2HEX(C36+D36*256+C37*2^16+D37*2^24) -> 180B170B | G37: ="DCW["&E37&"]("&F37&")" -> DCW[15](180B170B) | H37: =IF(B37=($B$4-1),"DCM("&E15&":"&F15&"; "&E17&":"&F17&"; "&E19&":"&F19&"; "&E21&":"&F21&"; "&E23&":"&F23&"; "&E25&":"&F25&"; "&E27&":"&F27&"; "&E29&":"&F29&"; "&E31&":"&F31&"; "&E33&":"&F33&"; "&E35&":"&F35&"; "&E37&":"&F37&")") -> FALSE | AB37: =1+AB36 -> 27 | AC37: =AB37+$AA$10 -> 133 | AD37: =IF($AJ$6=3, "V", "I") -> I | AE37: =IF(AD37="V",$AE$7,$AK$7) -> 9A523 | AH37: ="DCW["&AC37&"]("&AE37&")" -> DCW[133](9A523)
B38: =1+B37 -> 24 | C38: 11 | D38: 25 | E38: 16 | F38: =DEC2HEX(C38+D38*256) -> 190B | G38: ="DCW["&E38&"]("&F38&")" -> DCW[16](190B) | H38: =IF(B38=($B$4-1),"DCM("&E15&":"&F15&"; "&E17&":"&F17&"; "&E19&":"&F19&"; "&E21&":"&F21&"; "&E23&":"&F23&"; "&E25&":"&F25&"; "&E27&":"&F27&"; "&E29&":"&F29&"; "&E31&":"&F31&"; "&E33&":"&F33&"; "&E35&":"&F35&"; "&E37&":"&F37&"; "&E38&":"&F38&")") -> FALSE | AB38: =1+AB37 -> 28 | AC38: =AB38+$AA$10 -> 134 | AD38: =IF($AK$6=3, "V", "I") -> I | AE38: =IF(AD38="V",$AE$7,$AK$7) -> 9A523 | AH38: ="DCW["&AC38&"]("&AE38&")" -> DCW[134](9A523)
B39: =1+B38 -> 25 | C39: 11 | D39: 26 | E39: 16 | F39: =DEC2HEX(C38+D38*256+C39*2^16+D39*2^24) -> 1A0B190B | G39: ="DCW["&E39&"]("&F39&")" -> DCW[16](1A0B190B) | H39: =IF(B39=($B$4-1),"DCM("&E15&":"&F15&"; "&E17&":"&F17&"; "&E19&":"&F19&"; "&E21&":"&F21&"; "&E23&":"&F23&"; "&E25&":"&F25&"; "&E27&":"&F27&"; "&E29&":"&F29&"; "&E31&":"&F31&"; "&E33&":"&F33&"; "&E35&":"&F35&"; "&E37&":"&F37&"; "&E39&":"&F39&")") -> FALSE | AB39: =1+AB38 -> 29 | AC39: =AB39+$AA$10 -> 135 | AD39: =IF($AL$6=3, "V", "I") -> I | AE39: =IF(AD39="V",$AE$7,$AK$7) -> 9A523 | AH39: ="DCW["&AC39&"]("&AE39&")" -> DCW[135](9A523)
B40: =1+B39 -> 26 | C40: 11 | D40: 27 | E40: 17 | F40: =DEC2HEX(C40+D40*256) -> 1B0B | G40: ="DCW["&E40&"]("&F40&")" -> DCW[17](1B0B) | H40: =IF(B40=($B$4-1),"DCM("&E15&":"&F15&"; "&E17&":"&F17&"; "&E19&":"&F19&"; "&E21&":"&F21&"; "&E23&":"&F23&"; "&E25&":"&F25&"; "&E27&":"&F27&"; "&E29&":"&F29&"; "&E31&":"&F31&"; "&E33&":"&F33&"; "&E35&":"&F35&"; "&E37&":"&F37&"; "&E39&":"&F39&"; "&E40&":"&F40&")") -> FALSE | AB40: =1+AB39 -> 30 | AC40: =AB40+$AA$10 -> 136 | AD40: =IF($AM$6=3, "V", "I") -> I | AE40: =IF(AD40="V",$AE$7,$AK$7) -> 9A523 | AH40: ="DCW["&AC40&"]("&AE40&")" -> DCW[136](9A523)
...

Sheet AUX_INTERNAL
C1: DO NOT EDIT THIS SHEET. IT I SUSED FOR INTERNAL CALCULATIONS
C3: AFE SELECTION | D3: CH
C4: 1 x MCP3914. 8 channels and up to 7 powers are allowed. | D4: 8
C5: 2 x MCP3914. 16 channels and up to 15 powers are allowed. | D5: 16
C6: 3 x MCP3914. 24 channels and up to 23 powers are allowed. | D6: 24
C7: 4 x MCP3914. 32 channels and up to 31 powers are allowed. | D7: 32
C8: 1 x MCP3913. 6 channels and up to 5 powers are allowed. | D8: 6
C9: 2 x MCP3913. 12 channels and up to 11 powers are allowed | D9: 12
C10: 3 x MCP3913. 18 channels and up to 17 powers are allowed. | D10: 18
C11: 4 x MCP3913. 24 channels and up to 23 powers are allowed. | D11: 24
C15: SENSOR TYPES | D15: Index
C16: I(CT) | D16: 0
C17: I(RC) | D17: 1
C18: I(SH) | D18: 2
C19: V | D19: 3
C22: POWER MATRIX
C23: Ctrl reg | D23: Param | E23: COMMAND | F23: COMBINED CMD - POWER SOURCE REGISTERS | J23: COMBINED CMD - FROM SELECTION
C24: 4 | D24: =DEC2HEX(CONFIGURATOR!C21+CONFIGURATOR!D21*256) -> 300 | E24: ="DCW["&C24&"]("&D24&")" -> DCW[4](300) | F24: ="DCM("&C24&":"&D24&")" -> DCM(4:300) | J24: {=INDIRECT(ADDRESS(ROW(F24)+CONFIGURATOR!$L$16-1,6))} -> DCM(4:4000300; 5:6010500; 6:8010701; 7:A020902; 8:B02)
C25: 4 | D25: =DEC2HEX(CONFIGURATOR!C21+CONFIGURATOR!D21*256+CONFIGURATOR!C22*2^16+CONFIGURATOR!D22*2^24) -> 4000300 | E25: ="DCW["&C25&"]("&D25&")" -> DCW[4](4000300) | F25: ="DCM("&C25&":"&D25&")" -> DCM(4:4000300) | J25: COMBINED CMD - ALL REGISTERS
C26: 5 | D26: =DEC2HEX(CONFIGURATOR!C23+CONFIGURATOR!D23*256) -> 500 | E26: ="DCW["&C26&"]("&D26&")" -> DCW[5](500) | F26: ="DCM("&C25&":"&D25&"; "&C26&":"&D26&")" -> DCM(4:4000300; 5:500) | J26: =F54 -> DCM(4:4000300; 5:6010500; 6:8010701; 7:A020902; 8:B02; 9:0; 10:0; 11:0; 12:0; 13:0; 14:0; 15:0; 16:0; 17:0; 18:0; 19:0)
C27: 5 | D27: =DEC2HEX(CONFIGURATOR!C23+CONFIGURATOR!D23*256+CONFIGURATOR!C24*2^16+CONFIGURATOR!D24*2^24) -> 6010500 | E27: ="DCW["&C27&"]("&D27&")" -> DCW[5](6010500) | F27: ="DCM("&C25&":"&D25&"; "&C27&":"&D27&")" -> DCM(4:4000300; 5:6010500)
C28: 6 | D28: =DEC2HEX(CONFIGURATOR!C25+CONFIGURATOR!D25*256) -> 701 | E28: ="DCW["&C28&"]("&D28&")" -> DCW[6](701) | F28: ="DCM("&C25&":"&D25&"; "&C27&":"&D27&"; "&C28&":"&D28&")" -> DCM(4:4000300; 5:6010500; 6:701)
C29: 6 | D29: =DEC2HEX(CONFIGURATOR!C25+CONFIGURATOR!D25*256+CONFIGURATOR!C26*2^16+CONFIGURATOR!D26*2^24) -> 8010701 | E29: ="DCW["&C29&"]("&D29&")" -> DCW[6](8010701) | F29: ="DCM("&C25&":"&D25&"; "&C27&":"&D27&"; "&C29&":"&D29&")" -> DCM(4:4000300; 5:6010500; 6:8010701)
C30: 7 | D30: =DEC2HEX(CONFIGURATOR!C27+CONFIGURATOR!D27*256) -> 902 | E30: ="DCW["&C30&"]("&D30&")" -> DCW[7](902) | F30: ="DCM("&C25&":"&D25&"; "&C27&":"&D27&"; "&C29&":"&D29&"; "&C30&":"&D30&")" -> DCM(4:4000300; 5:6010500; 6:8010701; 7:902)
C31: 7 | D31: =DEC2HEX(CONFIGURATOR!C27+CONFIGURATOR!D27*256+CONFIGURATOR!C28*2^16+CONFIGURATOR!D28*2^24) -> A020902 | E31: ="DCW["&C31&"]("&D31&")" -> DCW[7](A020902) | F31: ="DCM("&C25&":"&D25&"; "&C27&":"&D27&"; "&C29&":"&D29&";"&C31&":"&D31&")" -> DCM(4:4000300; 5:6010500; 6:8010701;7:A020902)
C32: 8 | D32: =DEC2HEX(CONFIGURATOR!C29+CONFIGURATOR!D29*256) -> B02 | E32: ="DCW["&C32&"]("&D32&")" -> DCW[8](B02) | F32: ="DCM("&C25&":"&D25&"; "&C27&":"&D27&"; "&C29&":"&D29&"; "&C31&":"&D31&"; "&C32&":"&D32&")" -> DCM(4:4000300; 5:6010500; 6:8010701; 7:A020902; 8:B02)
C33: 8 | D33: =DEC2HEX(CONFIGURATOR!C29+CONFIGURATOR!D29*256+CONFIGURATOR!C30*2^16+CONFIGURATOR!D30*2^24) -> B02 | E33: ="DCW["&C33&"]("&D33&")" -> DCW[8](B02) | F33: ="DCM("&C25&":"&D25&"; "&C27&":"&D27&"; "&C29&":"&D29&"; "&C31&":"&D31&"; "&C33&":"&D33&")" -> DCM(4:4000300; 5:6010500; 6:8010701; 7:A020902; 8:B02)
C34: 9 | D34: =DEC2HEX(CONFIGURATOR!C31+CONFIGURATOR!D31*256) -> 0 | E34: ="DCW["&C34&"]("&D34&")" -> DCW[9](0) | F34: ="DCM("&C25&":"&D25&"; "&C27&":"&D27&"; "&C29&":"&D29&"; "&C31&":"&D31&"; "&C33&":"&D33&"; "&C34&":"&D34&")" -> DCM(4:4000300; 5:6010500; 6:8010701; 7:A020902; 8:B02; 9:0)
C35: 9 | D35: =DEC2HEX(CONFIGURATOR!C31+CONFIGURATOR!D31*256+CONFIGURATOR!C32*2^16+CONFIGURATOR!D32*2^24) -> 0 | E35: ="DCW["&C35&"]("&D35&")" -> DCW[9](0) | F35: ="DCM("&C25&":"&D25&"; "&C27&":"&D27&"; "&C29&":"&D29&"; "&C31&":"&D31&"; "&C33&":"&D33&"; "&C35&":"&D35&")" -> DCM(4:4000300; 5:6010500; 6:8010701; 7:A020902; 8:B02; 9:0)
C36: 10 | D36: =DEC2HEX(CONFIGURATOR!C33+CONFIGURATOR!D33*256) -> 0 | E36: ="DCW["&C36&"]("&D36&")" -> DCW[10](0) | F36: ="DCM("&C25&":"&D25&"; "&C27&":"&D27&"; "&C29&":"&D29&"; "&C31&":"&D31&"; "&C33&":"&D33&"; "&C35&":"&D35&"; "&C36&":"&D36&")" -> DCM(4:4000300; 5:6010500; 6:8010701; 7:A020902; 8:B02; 9:0; 10:0)
C37: 10 | D37: =DEC2HEX(CONFIGURATOR!C33+CONFIGURATOR!D33*256+CONFIGURATOR!C34*2^16+CONFIGURATOR!D34*2^24) -> 0 | E37: ="DCW["&C37&"]("&D37&")" -> DCW[10](0) | F37: ="DCM("&C25&":"&D25&"; "&C27&":"&D27&"; "&C29&":"&D29&"; "&C31&":"&D31&"; "&C33&":"&D33&"; "&C35&":"&D35&"; "&C37&":"&D37&")" -> DCM(4:4000300; 5:6010500; 6:8010701; 7:A020902; 8:B02; 9:0; 10:0)
C38: 11 | D38: =DEC2HEX(CONFIGURATOR!C35+CONFIGURATOR!D35*256) -> 0 | E38: ="DCW["&C38&"]("&D38&")" -> DCW[11](0) | F38: ="DCM("&C25&":"&D25&"; "&C27&":"&D27&"; "&C29&":"&D29&"; "&C31&":"&D31&"; "&C33&":"&D33&"; "&C35&":"&D35&"; "&C37&":"&D37&"; "&C38&":"&D38&")" -> DCM(4:4000300; 5:6010500; 6:8010701; 7:A020902; 8:B02; 9:0; 10:0; 11:0)
C39: 11 | D39: =DEC2HEX(CONFIGURATOR!C35+CONFIGURATOR!D35*256+CONFIGURATOR!C36*2^16+CONFIGURATOR!D36*2^24) -> 0 | E39: ="DCW["&C39&"]("&D39&")" -> DCW[11](0) | F39: ="DCM("&C25&":"&D25&"; "&C27&":"&D27&"; "&C29&":"&D29&"; "&C31&":"&D31&"; "&C33&":"&D33&"; "&C35&":"&D35&"; "&C37&":"&D37&"; "&C39&":"&D39&")" -> DCM(4:4000300; 5:6010500; 6:8010701; 7:A020902; 8:B02; 9:0; 10:0; 11:0)
C40: 12 | D40: =DEC2HEX(CONFIGURATOR!C37+CONFIGURATOR!D37*256) -> 0 | E40: ="DCW["&C40&"]("&D40&")" -> DCW[12](0) | F40: ="DCM("&C25&":"&D25&"; "&C27&":"&D27&"; "&C29&":"&D29&";"&C31&":"&D31&"; "&C33&":"&D33&"; "&C35&":"&D35&"; "&C37&":"&D37&"; "&C39&":"&D39&"; "&C40&":"&D40&")" -> DCM(4:4000300; 5:6010500; 6:8010701;7:A020902; 8:B02; 9:0; 10:0; 11:0; 12:0)
C41: 12 | D41: =DEC2HEX(CONFIGURATOR!C37+CONFIGURATOR!D37*256+CONFIGURATOR!C38*2^16+CONFIGURATOR!D38*2^24) -> 0 | E41: ="DCW["&C41&"]("&D41&")" -> DCW[12](0) | F41: ="DCM("&C25&":"&D25&"; "&C27&":"&D27&"; "&C29&":"&D29&"; "&C31&":"&D31&"; "&C33&":"&D33&"; "&C35&":"&D35&"; "&C37&":"&D37&"; "&C39&":"&D39&"; "&C41&":"&D41&")" -> DCM(4:4000300; 5:6010500; 6:8010701; 7:A020902; 8:B02; 9:0; 10:0; 11:0; 12:0)
C42: 13 | D42: =DEC2HEX(CONFIGURATOR!C39+CONFIGURATOR!D39*256) -> 0 | E42: ="DCW["&C42&"]("&D42&")" -> DCW[13](0) | F42: ="DCM("&C25&":"&D25&"; "&C27&":"&D27&"; "&C29&":"&D29&"; "&C31&":"&D31&"; "&C33&":"&D33&"; "&C35&":"&D35&"; "&C37&":"&D37&"; "&C39&":"&D39&"; "&C41&":"&D41&"; "&C42&":"&D42&")" -> DCM(4:4000300; 5:6010500; 6:8010701; 7:A020902; 8:B02; 9:0; 10:0; 11:0; 12:0; 13:0)
C43: 13 | D43: =DEC2HEX(CONFIGURATOR!C39+CONFIGURATOR!D39*256+CONFIGURATOR!C40*2^16+CONFIGURATOR!D40*2^24) -> 0 | E43: ="DCW["&C43&"]("&D43&")" -> DCW[13](0) | F43: ="DCM("&C25&":"&D25&"; "&C27&":"&D27&"; "&C29&":"&D29&"; "&C31&":"&D31&"; "&C33&":"&D33&"; "&C35&":"&D35&"; "&C37&":"&D37&"; "&C39&":"&D39&"; "&C41&":"&D41&"; "&C43&":"&D43&")" -> DCM(4:4000300; 5:6010500; 6:8010701; 7:A020902; 8:B02; 9:0; 10:0; 11:0; 12:0; 13:0)
C44: 14 | D44: =DEC2HEX(CONFIGURATOR!C41+CONFIGURATOR!D41*256) -> 0 | E44: ="DCW["&C44&"]("&D44&")" -> DCW[14](0) | F44: ="DCM("&C25&":"&D25&"; "&C27&":"&D27&"; "&C29&":"&D29&"; "&C31&":"&D31&"; "&C33&":"&D33&"; "&C35&":"&D35&"; "&C37&":"&D37&"; "&C39&":"&D39&"; "&C41&":"&D41&"; "&C43&":"&D43&"; "&C44&":"&D44&")" -> DCM(4:4000300; 5:6010500; 6:8010701; 7:A020902; 8:B02; 9:0; 10:0; 11:0; 12:0; 13:0; 14:0)
C45: 14 | D45: =DEC2HEX(CONFIGURATOR!C41+CONFIGURATOR!D41*256+CONFIGURATOR!C42*2^16+CONFIGURATOR!D42*2^24) -> 0 | E45: ="DCW["&C45&"]("&D45&")" -> DCW[14](0) | F45: ="DCM("&C25&":"&D25&"; "&C27&":"&D27&"; "&C29&":"&D29&"; "&C31&":"&D31&"; "&C33&":"&D33&"; "&C35&":"&D35&"; "&C37&":"&D37&"; "&C39&":"&D39&"; "&C41&":"&D41&"; "&C43&":"&D43&"; "&C45&":"&D45&")" -> DCM(4:4000300; 5:6010500; 6:8010701; 7:A020902; 8:B02; 9:0; 10:0; 11:0; 12:0; 13:0; 14:0)
C46: 15 | D46: =DEC2HEX(CONFIGURATOR!C43+CONFIGURATOR!D43*256) -> 0 | E46: ="DCW["&C46&"]("&D46&")" -> DCW[15](0) | F46: ="DCM("&C25&":"&D25&"; "&C27&":"&D27&"; "&C29&":"&D29&"; "&C31&":"&D31&"; "&C33&":"&D33&"; "&C35&":"&D35&"; "&C37&":"&D37&"; "&C39&":"&D39&"; "&C41&":"&D41&"; "&C43&":"&D43&"; "&C45&":"&D45&"; "&C46&":"&D46&")" -> DCM(4:4000300; 5:6010500; 6:8010701; 7:A020902; 8:B02; 9:0; 10:0; 11:0; 12:0; 13:0; 14:0; 15:0)
...

Sheet CALCULATIONS MCP
AH3: CALIBRATION
AR4: =AR9*220/219.97 -> 1.0222845 | AT4: =DEC2HEX(INT(AR4*2^29+0.5),8) -> 20B68DEB
D5: CONTROL REGISTERS | N5: STATUS REGISTERS | X5: ACCUMULATOR REGISTERS | AJ5: First power index where the current with index="channel" is contributing
A6: ='CALIBRATION GUIDE'!B57 -> PAR[I] | D6: R | E6: I | G6: ID | H6: NAME | I6: VALUE | J6: FORMAT | K6: DECIMAL | L6: DERIVED QUANTITIES | N6: R | O6: I | Q6: ID | R6: NAME | S6: VALUE | T6: FORMAT | U6: DECIMAL | V6: DERIVED QUANTITIES | X6: R | Y6: I | AA6: ID | AB6: NAME | AC6: VALUE | AD6: FORMAT | AE6: DECIMAL | AF6: DERIVED QUANTITIES | AH6: CHANNEL | AI6: V/I | AJ6: POWER ID | AK6: P(POWER ID) | AL6: Q(POWER ID) | AM6: Angle | AN6: MEASURED | AO6: APPLIED | AP6: CAL_M_old (60Hz) | AQ6: Delta_cal | AR6: CAL_M | AS6: REG | AT6: HEX | AU6: CAL_PH_old (60Hz) | AV6: Delta_cal(50Hz) | AW6: Delta_cal(60Hz) | AX6: CAL_PH | AY6: REG | AZ6: HEX | BA6: COMBINED M CMD
A7: ='CALIBRATION GUIDE'!B58 -> Present RMS values are : | D7: 27 | E7: 1 | G7: =MID(INDIRECT(ADDRESS(D7,1)),(E7-1)*19+1,3) -> 000 | H7: =TRIM(MID(INDIRECT(ADDRESS(D7,1)),(E7-1)*19+4,16)) -> STATE_CTRL | I7: =TRIM(MID(INDIRECT(ADDRESS(D7+1,1)),(E7-1)*19+1,19)) -> 2 | J7: uQ32.0 | K7: =(HEX2DEC(LEFT(REPT("0",16-LEN(I7))&I7,10))*16^6+HEX2DEC(RIGHT(I7,6)))/2^(0+MID(J7,FIND(".",J7)+1,2)) -> 2 | N7: 170 | O7: 1 | Q7: =MID(INDIRECT(ADDRESS(N7,1)),(O7-1)*19+1,3) -> 000 | R7: =TRIM(MID(INDIRECT(ADDRESS(N7,1)),(O7-1)*19+4,16)) -> VERSION | S7: =TRIM(MID(INDIRECT(ADDRESS(N7+1,1)),(O7-1)*19+1,19)) -> 40000 | T7: uQ32.0 | U7: =(HEX2DEC(LEFT(REPT("0",16-LEN(S7))&S7,10))*16^6+HEX2DEC(RIGHT(S7,6)))/2^(0+MID(T7,FIND(".",T7)+1,2)) -> 262144 | X7: 233 | Y7: 1 | AA7: =MID(INDIRECT(ADDRESS(X7,1)),(Y7-1)*19+1,3) -> 000 | AB7: =TRIM(MID(INDIRECT(ADDRESS(X7,1)),(Y7-1)*19+4,16)) -> CH0 | AC7: =TRIM(MID(INDIRECT(ADDRESS(X7+1,1)),(Y7-1)*19+1,19)) -> 43E625E2D4D1 | AD7: uQ24.40 | AE7: =(HEX2DEC(LEFT(REPT("0",16-LEN(AC7))&AC7,10))*16^6+HEX2DEC(RIGHT(AC7,6)))/2^(0+MID(AD7,FIND(".",AD7)+1,2)) -> 67.899016 | AF7: =SQRT(AE7/$U$16)*K113 -> 215.10416 | AH7: ='CALIBRATION GUIDE'!B13 -> 0 | AI7: ='CALIBRATION GUIDE'!C13 -> V | AJ7: =IF('CALIBRATION GUIDE'!C13="V"," ", IF(ISNA(MATCH(AH7,CONFIGURATOR!$D$21:$D$51,0))=TRUE," ",MATCH(AH7,CONFIGURATOR!$D$21:$D$51,0)-1) ) | AK7: {=IF(AJ7=" "," ",INDIRECT(ADDRESS(103+AJ7,31)))} | AL7: {=IF(AJ7=" "," ",INDIRECT(ADDRESS(135+AJ7,31)))} | AM7: =IF(AJ7=" ", " ", IF(OR(AK7=0,AL7=0),0, DEGREES(ATAN2(AK7,AL7)))) | AN7: =AF7 -> 215.10416 | AO7: ='CALIBRATION GUIDE'!D13 -> 220 | AP7: =K145 -> 1 | AQ7: =IF(AN7>0,AO7/AN7,1) -> 1.0227603 | AR7: =IF((AQ7*AP7)<4,AQ7*AP7,1) -> 1.0227603 | AS7: 138 | AT7: =IF('CALIBRATION GUIDE'!E13="Y",RIGHT(DEC2HEX(INT(AR7*2^29+0.5),8),8)," ") -> 20BA73D2 | AU7: =K177 -> 0 | AV7: =IF(AM7=" ",0,AM7-'CALIBRATION GUIDE'!$C$8) -> 0 | AW7: =IF(AV7=0, 0, AV7*60/'CALIBRATION GUIDE'!$C$7) -> 0 | AX7: =AW7+AU7 -> 0 | AY7: 170 | AZ7: =IF('CALIBRATION GUIDE'!E13="Y",IF(AI7="V",0,RIGHT(DEC2HEX((AX7)/180*2^31),8)), " ") -> 0 | BA7: ="DCM(" & IF(AT7=" ", "", AS7&":"&AT7) & IF(AT8=" ", "", "; "&AS8&":"&AT8) & IF(AT9=" ", "", "; "& AS9&":"&AT9) & IF(AT10=" ", "", "; "&AS10&":"&AT10) & IF(AT11=" ", "", "; "&AS11&":"&AT11) & IF(AT12=" ", "", "; "&AS12&":"&AT12) & IF(AT13=" ", "", "; "&AS13&":"&AT13) & IF(AT14=" ", "", "; "&AS14&":"&AT14) & IF(AT15=" ", "", "; "&AS15&":"&AT15) & IF(AT16=" ", "", "; "&AS16&":"&AT16) & IF(AT17=" ", "", "; "&AS17&":"&AT17) & IF(AT18=" ", "", "; "&AS18&":"&AT18) & IF(AT19=" ", "", "; "&AS19&":"&AT19) & IF(AT20=" ", "", "; "&AS20&":"&AT20) & IF(AT21=" ", "", "; "&AS21&":"&AT21) & IF(AT22=" ", "", "; "&AS22&":"&AT22) & IF(AT23=" ", "", "; "& AS23&":"&AT23) & IF(AT24=" ", "", "; "& AS24&":"&AT24) & IF(AT25=" ", "", "; "&AS25&":"&AT25) & IF(AT26=" ", "", "; "&AS26&":"&AT26) & IF(AT27=" ", "", "; "&AS27&":"&AT27) & IF(AT28=" ", "", "; "&AS28&":"&AT28) & IF(AT29=" ", "", "; "&AS29&":"&AT29) & IF(AT30=" ", "", "; "&AS30&":"&AT30) & IF(AT31=" ", "", "; "&AS31&":"&AT31) &IF(AT32=" ", "", "; "&AS32&":"&AT32) & IF(AT33=" ", "", "; "&AS33&":"&AT33) & IF(AT34=" ", "", "; "&AS34&":"&AT34) & IF(AT35=" ", "", "; "&AS35&":"&AT35) & IF(AT36=" ", "", "; "&AS36&":"&AT36) & IF(AT37=" ", "", "; "&AS37&":"&AT37) & IF(AT38=" ", "", "; "&AS38&":"&AT38) &")" -> DCM(138:20BA73D2; 139:20B77771; 140:20B56992; 141:1F5D9BA8; 142:1F73A467; 143:1F74DAC6)
A8: ='CALIBRATION GUIDE'!B59 -> CH00=215.114V CH01=215.121V CH02=215.170V CH03=30.600A | D8: 27 | E8: 2 | G8: =MID(INDIRECT(ADDRESS(D8,1)),(E8-1)*19+1,3) -> 001 | H8: =TRIM(MID(INDIRECT(ADDRESS(D8,1)),(E8-1)*19+4,16)) -> FEATURE_CTRL0 | I8: =TRIM(MID(INDIRECT(ADDRESS(D8+1,1)),(E8-1)*19+1,19)) -> 300 | J8: uQ32.0 | K8: =(HEX2DEC(LEFT(REPT("0",16-LEN(I8))&I8,10))*16^6+HEX2DEC(RIGHT(I8,6)))/2^(0+MID(J8,FIND(".",J8)+1,2)) -> 768 | N8: 170 | O8: 2 | Q8: =MID(INDIRECT(ADDRESS(N8,1)),(O8-1)*19+1,3) -> 001 | R8: =TRIM(MID(INDIRECT(ADDRESS(N8,1)),(O8-1)*19+4,16)) -> STATUS | S8: =TRIM(MID(INDIRECT(ADDRESS(N8+1,1)),(O8-1)*19+1,19)) -> 8 | T8: uQ32.0 | U8: =(HEX2DEC(LEFT(REPT("0",16-LEN(S8))&S8,10))*16^6+HEX2DEC(RIGHT(S8,6)))/2^(0+MID(T8,FIND(".",T8)+1,2)) -> 8 | X8: 233 | Y8: 2 | AA8: =MID(INDIRECT(ADDRESS(X8,1)),(Y8-1)*19+1,3) -> 001 | AB8: =TRIM(MID(INDIRECT(ADDRESS(X8,1)),(Y8-1)*19+4,16)) -> CH1 | AC8: =TRIM(MID(INDIRECT(ADDRESS(X8+1,1)),(Y8-1)*19+1,19)) -> 43F28B30BCA2 | AD8: uQ24.40 | AE8: =(HEX2DEC(LEFT(REPT("0",16-LEN(AC8))&AC8,10))*16^6+HEX2DEC(RIGHT(AC8,6)))/2^(0+MID(AD8,FIND(".",AD8)+1,2)) -> 67.947436 | AF8: =SQRT(AE8/$U$16)*K114 -> 215.18085 | AH8: ='CALIBRATION GUIDE'!B14 -> 1 | AI8: ='CALIBRATION GUIDE'!C14 -> V | AJ8: =IF('CALIBRATION GUIDE'!C14="V"," ", IF(ISNA(MATCH(AH8,CONFIGURATOR!$D$21:$D$51,0))=TRUE," ",MATCH(AH8,CONFIGURATOR!$D$21:$D$51,0)-1) ) | AK8: {=IF(AJ8=" "," ",INDIRECT(ADDRESS(103+AJ8,31)))} | AL8: {=IF(AJ8=" "," ",INDIRECT(ADDRESS(135+AJ8,31)))} | AM8: =IF(AJ8=" ", " ", IF(OR(AK8=0,AL8=0),0, DEGREES(ATAN2(AK8,AL8)))) | AN8: =AF8 -> 215.18085 | AO8: ='CALIBRATION GUIDE'!D14 -> 220 | AP8: =K146 -> 1 | AQ8: =IF(AN8>0,AO8/AN8,1) -> 1.0223958 | AR8: =IF((AQ8*AP8)<4,AQ8*AP8,1) -> 1.0223958 | AS8: =1+AS7 -> 139 | AT8: =IF('CALIBRATION GUIDE'!E14="Y",RIGHT(DEC2HEX(INT(AR8*2^29+0.5),8),8)," ") -> 20B77771 | AU8: =K178 -> 0 | AV8: =IF(AM8=" ",0,AM8-'CALIBRATION GUIDE'!$C$8) -> 0 | AW8: =IF(AV8=0, 0, AV8*60/'CALIBRATION GUIDE'!$C$7) -> 0 | AX8: =AW8+AU8 -> 0 | AY8: =1+AY7 -> 171 | AZ8: =IF('CALIBRATION GUIDE'!E14="Y",IF(AI8="V",0,RIGHT(DEC2HEX((AX8)/180*2^31),8)), " ") -> 0
A9: ='CALIBRATION GUIDE'!B60 -> CH04=30.520A CH05=30.518A CH06=0.004A CH07=0.009V | D9: 27 | E9: 3 | G9: =MID(INDIRECT(ADDRESS(D9,1)),(E9-1)*19+1,3) -> 002 | H9: =TRIM(MID(INDIRECT(ADDRESS(D9,1)),(E9-1)*19+4,16)) -> FEATURE_CTRL1 | I9: =TRIM(MID(INDIRECT(ADDRESS(D9+1,1)),(E9-1)*19+1,19)) -> 0 | J9: uQ32.0 | K9: =(HEX2DEC(LEFT(REPT("0",16-LEN(I9))&I9,10))*16^6+HEX2DEC(RIGHT(I9,6)))/2^(0+MID(J9,FIND(".",J9)+1,2)) -> 0 | N9: 170 | O9: 3 | Q9: =MID(INDIRECT(ADDRESS(N9,1)),(O9-1)*19+1,3) -> 002 | R9: =TRIM(MID(INDIRECT(ADDRESS(N9,1)),(O9-1)*19+4,16)) -> STATE_FLAG | S9: =TRIM(MID(INDIRECT(ADDRESS(N9+1,1)),(O9-1)*19+1,19)) -> 20 | T9: uQ32.0 | U9: =(HEX2DEC(LEFT(REPT("0",16-LEN(S9))&S9,10))*16^6+HEX2DEC(RIGHT(S9,6)))/2^(0+MID(T9,FIND(".",T9)+1,2)) -> 32 | X9: 233 | Y9: 3 | AA9: =MID(INDIRECT(ADDRESS(X9,1)),(Y9-1)*19+1,3) -> 002 | AB9: =TRIM(MID(INDIRECT(ADDRESS(X9,1)),(Y9-1)*19+4,16)) -> CH2 | AC9: =TRIM(MID(INDIRECT(ADDRESS(X9+1,1)),(Y9-1)*19+1,19)) -> 43FB144B5222 | AD9: uQ24.40 | AE9: =(HEX2DEC(LEFT(REPT("0",16-LEN(AC9))&AC9,10))*16^6+HEX2DEC(RIGHT(AC9,6)))/2^(0+MID(AD9,FIND(".",AD9)+1,2)) -> 67.980778 | AF9: =SQRT(AE9/$U$16)*K115 -> 215.23364 | AH9: ='CALIBRATION GUIDE'!B15 -> 2 | AI9: ='CALIBRATION GUIDE'!C15 -> V | AJ9: =IF('CALIBRATION GUIDE'!C15="V"," ", IF(ISNA(MATCH(AH9,CONFIGURATOR!$D$21:$D$51,0))=TRUE," ",MATCH(AH9,CONFIGURATOR!$D$21:$D$51,0)-1) ) | AK9: {=IF(AJ9=" "," ",INDIRECT(ADDRESS(103+AJ9,31)))} | AL9: {=IF(AJ9=" "," ",INDIRECT(ADDRESS(135+AJ9,31)))} | AM9: =IF(AJ9=" ", " ", IF(OR(AK9=0,AL9=0),0, DEGREES(ATAN2(AK9,AL9)))) | AN9: =AF9 -> 215.23364 | AO9: ='CALIBRATION GUIDE'!D15 -> 220 | AP9: =K147 -> 1 | AQ9: =IF(AN9>0,AO9/AN9,1) -> 1.0221451 | AR9: =IF((AQ9*AP9)<4,AQ9*AP9,1) -> 1.0221451 | AS9: =1+AS8 -> 140 | AT9: =IF('CALIBRATION GUIDE'!E15="Y",RIGHT(DEC2HEX(INT(AR9*2^29+0.5),8),8)," ") -> 20B56992 | AU9: =K179 -> 0 | AV9: =IF(AM9=" ",0,AM9-'CALIBRATION GUIDE'!$C$8) -> 0 | AW9: =IF(AV9=0, 0, AV9*60/'CALIBRATION GUIDE'!$C$7) -> 0 | AX9: =AW9+AU9 -> 0 | AY9: =1+AY8 -> 172 | AZ9: =IF('CALIBRATION GUIDE'!E15="Y",IF(AI9="V",0,RIGHT(DEC2HEX((AX9)/180*2^31),8)), " ") -> 0 | BA9: COMBINED PH CMD
A10: ='CALIBRATION GUIDE'!B61 -> CH08=0.000A CH09=0.000V CH10=0.000A CH11=0.000V | D10: 27 | E10: 4 | G10: =MID(INDIRECT(ADDRESS(D10,1)),(E10-1)*19+1,3) -> 003 | H10: =TRIM(MID(INDIRECT(ADDRESS(D10,1)),(E10-1)*19+4,16)) -> RESERVED_C003 | I10: =TRIM(MID(INDIRECT(ADDRESS(D10+1,1)),(E10-1)*19+1,19)) -> 0 | J10: uQ32.0 | K10: =(HEX2DEC(LEFT(REPT("0",16-LEN(I10))&I10,10))*16^6+HEX2DEC(RIGHT(I10,6)))/2^(0+MID(J10,FIND(".",J10)+1,2)) -> 0 | N10: 170 | O10: 4 | Q10: =MID(INDIRECT(ADDRESS(N10,1)),(O10-1)*19+1,3) -> 003 | R10: =TRIM(MID(INDIRECT(ADDRESS(N10,1)),(O10-1)*19+4,16)) -> SWELL_OV_FLAG | S10: =TRIM(MID(INDIRECT(ADDRESS(N10+1,1)),(O10-1)*19+1,19)) -> 5 | T10: uQ32.0 | U10: =(HEX2DEC(LEFT(REPT("0",16-LEN(S10))&S10,10))*16^6+HEX2DEC(RIGHT(S10,6)))/2^(0+MID(T10,FIND(".",T10)+1,2)) -> 5 | X10: 233 | Y10: 4 | AA10: =MID(INDIRECT(ADDRESS(X10,1)),(Y10-1)*19+1,3) -> 003 | AB10: =TRIM(MID(INDIRECT(ADDRESS(X10,1)),(Y10-1)*19+4,16)) -> CH3 | AC10: =TRIM(MID(INDIRECT(ADDRESS(X10+1,1)),(Y10-1)*19+1,19)) -> 9D576EF0D84 | AD10: uQ24.40 | AE10: =(HEX2DEC(LEFT(REPT("0",16-LEN(AC10))&AC10,10))*16^6+HEX2DEC(RIGHT(AC10,6)))/2^(0+MID(AD10,FIND(".",AD10)+1,2)) -> 9.833846 | AF10: =SQRT(AE10/$U$16)*K116 -> 30.606724 | AH10: ='CALIBRATION GUIDE'!B16 -> 3 | AI10: ='CALIBRATION GUIDE'!C16 -> I(CT) | AJ10: =IF('CALIBRATION GUIDE'!C16="V"," ", IF(ISNA(MATCH(AH10,CONFIGURATOR!$D$21:$D$51,0))=TRUE," ",MATCH(AH10,CONFIGURATOR!$D$21:$D$51,0)-1) ) -> 0 | AK10: {=IF(AJ10=" "," ",INDIRECT(ADDRESS(103+AJ10,31)))} -> 12.939915 | AL10: {=IF(AJ10=" "," ",INDIRECT(ADDRESS(135+AJ10,31)))} -> 22.361716 | AM10: =IF(AJ10=" ", " ", IF(OR(AK10=0,AL10=0),0, DEGREES(ATAN2(AK10,AL10)))) -> 59.943588 | AN10: =AF10 -> 30.606724 | AO10: ='CALIBRATION GUIDE'!D16 -> 30 | AP10: =K148 -> 1 | AQ10: =IF(AN10>0,AO10/AN10,1) -> 0.98017676 | AR10: =IF((AQ10*AP10)<4,AQ10*AP10,1) -> 0.98017676 | AS10: =1+AS9 -> 141 | AT10: =IF('CALIBRATION GUIDE'!E16="Y",RIGHT(DEC2HEX(INT(AR10*2^29+0.5),8),8)," ") -> 1F5D9BA8 | AU10: =K180 -> 0 | AV10: =IF(AM10=" ",0,AM10-'CALIBRATION GUIDE'!$C$8) -> -0.056411867 | AW10: =IF(AV10=0, 0, AV10*60/'CALIBRATION GUIDE'!$C$7) -> -0.06769424 | AX10: =AW10+AU10 -> -0.06769424 | AY10: =1+AY9 -> 173 | AZ10: =IF('CALIBRATION GUIDE'!E16="Y",IF(AI10="V",0,RIGHT(DEC2HEX((AX10)/180*2^31),8)), " ") -> FFF3AD39 | BA10: ="DCM(" & IF(AZ7=" ", "", AY7&":"&AZ7) & IF(AZ8=" ", "", "; "&AY8&":"&AZ8) & IF(AZ9=" ", "", "; "& AY9&":"&AZ9) & IF(AZ10=" ", "", "; "&AY10&":"&AZ10) & IF(AZ11=" ", "", "; "&AY11&":"&AZ11) & IF(AZ12=" ", "", "; "&AY12&":"&AZ12) & IF(AZ13=" ", "", "; "&AY13&":"&AZ13) & IF(AZ14=" ", "", "; "&AY14&":"&AZ14) & IF(AZ15=" ", "", "; "&AY15&":"&AZ15) & IF(AZ16=" ", "", "; "&AY16&":"&AZ16) & IF(AZ17=" ", "", "; "&AY17&":"&AZ17) & IF(AZ18=" ", "", "; "&AY18&":"&AZ18) & IF(AZ19=" ", "", "; "&AY19&":"&AZ19) & IF(AZ20=" ", "", "; "&AY20&":"&AZ20) & IF(AZ21=" ", "", "; "&AY21&":"&AZ21) & IF(AZ22=" ", "", "; "&AY22&":"&AZ22) & IF(AZ23=" ", "", "; "& AY23&":"&AZ23) & IF(AZ24=" ", "", "; "& AY24&":"&AZ24) & IF(AZ25=" ", "", "; "&AY25&":"&AZ25) & IF(AZ26=" ", "", "; "&AY26&":"&AZ26) & IF(AZ27=" ", "", "; "&AY27&":"&AZ27) & IF(AZ28=" ", "", "; "&AY28&":"&AZ28) & IF(AZ29=" ", "", "; "&AY29&":"&AZ29) & IF(AZ30=" ", "", "; "&AY30&":"&AZ30) & IF(AZ31=" ", "", "; "&AY31&":"&AZ31) &IF(AZ32=" ", "", "; "&AY32&":"&AZ32) & IF(AZ33=" ", "", "; "&AY33&":"&AZ33) & IF(AZ34=" ", "", "; "&AY34&":"&AZ34) & IF(AZ35=" ", "", "; "&AY35&":"&AZ35) & IF(AZ36=" ", "", "; "&AY36&":"&AZ36) & IF(AZ37=" ", "", "; "&AY37&":"&AZ37) & IF(AZ38=" ", "", "; "&AY38&":"&AZ38) &")" -> DCM(170:0; 171:0; 172:0; 173:FFF3AD39; 174:FFF22FC1; 175:FFF0A58D)
A11: ='CALIBRATION GUIDE'!B62 -> CH12=0.000A CH13=0.000A CH14=0.000A CH15=0.000A | D11: =D7+2 -> 29 | E11: 1 | G11: =MID(INDIRECT(ADDRESS(D11,1)),(E11-1)*19+1,3) -> 004 | H11: =TRIM(MID(INDIRECT(ADDRESS(D11,1)),(E11-1)*19+4,16)) -> PH_SRC_0_1 | I11: =TRIM(MID(INDIRECT(ADDRESS(D11+1,1)),(E11-1)*19+1,19)) -> 4010300 | J11: uQ32.0 | K11: =(HEX2DEC(LEFT(REPT("0",16-LEN(I11))&I11,10))*16^6+HEX2DEC(RIGHT(I11,6)))/2^(0+MID(J11,FIND(".",J11)+1,2)) -> 67175168 | N11: =N7+2 -> 172 | O11: 1 | Q11: =MID(INDIRECT(ADDRESS(N11,1)),(O11-1)*19+1,3) -> 004 | R11: =TRIM(MID(INDIRECT(ADDRESS(N11,1)),(O11-1)*19+4,16)) -> SAG_FLAG | S11: =TRIM(MID(INDIRECT(ADDRESS(N11+1,1)),(O11-1)*19+1,19)) -> 80 | T11: uQ32.0 | U11: =(HEX2DEC(LEFT(REPT("0",16-LEN(S11))&S11,10))*16^6+HEX2DEC(RIGHT(S11,6)))/2^(0+MID(T11,FIND(".",T11)+1,2)) -> 128 | X11: =X7+2 -> 235 | Y11: 1 | AA11: =MID(INDIRECT(ADDRESS(X11,1)),(Y11-1)*19+1,3) -> 004 | AB11: =TRIM(MID(INDIRECT(ADDRESS(X11,1)),(Y11-1)*19+4,16)) -> CH4 | AC11: =TRIM(MID(INDIRECT(ADDRESS(X11+1,1)),(Y11-1)*19+1,19)) -> 9C7B46F175B | AD11: uQ24.40 | AE11: =(HEX2DEC(LEFT(REPT("0",16-LEN(AC11))&AC11,10))*16^6+HEX2DEC(RIGHT(AC11,6)))/2^(0+MID(AD11,FIND(".",AD11)+1,2)) -> 9.780097 | AF11: =SQRT(AE11/$U$16)*K117 -> 30.522966 | AH11: ='CALIBRATION GUIDE'!B17 -> 4 | AI11: ='CALIBRATION GUIDE'!C17 -> I(CT) | AJ11: =IF('CALIBRATION GUIDE'!C17="V"," ", IF(ISNA(MATCH(AH11,CONFIGURATOR!$D$21:$D$51,0))=TRUE," ",MATCH(AH11,CONFIGURATOR!$D$21:$D$51,0)-1) ) -> 1 | AK11: {=IF(AJ11=" "," ",INDIRECT(ADDRESS(103+AJ11,31)))} -> 12.917101 | AL11: {=IF(AJ11=" "," ",INDIRECT(ADDRESS(135+AJ11,31)))} -> 22.316162 | AM11: =IF(AJ11=" ", " ", IF(OR(AK11=0,AL11=0),0, DEGREES(ATAN2(AK11,AL11)))) -> 59.936767 | AN11: =AF11 -> 30.522966 | AO11: ='CALIBRATION GUIDE'!D17 -> 30 | AP11: =K149 -> 1 | AQ11: =IF(AN11>0,AO11/AN11,1) -> 0.98286648 | AR11: =IF((AQ11*AP11)<4,AQ11*AP11,1) -> 0.98286648 | AS11: =1+AS10 -> 142 | AT11: =IF('CALIBRATION GUIDE'!E17="Y",RIGHT(DEC2HEX(INT(AR11*2^29+0.5),8),8)," ") -> 1F73A467 | AU11: =K181 -> 0 | AV11: =IF(AM11=" ",0,AM11-'CALIBRATION GUIDE'!$C$8) -> -0.063233033 | AW11: =IF(AV11=0, 0, AV11*60/'CALIBRATION GUIDE'!$C$7) -> -0.07587964 | AX11: =AW11+AU11 -> -0.07587964 | AY11: =1+AY10 -> 174 | AZ11: =IF('CALIBRATION GUIDE'!E17="Y",IF(AI11="V",0,RIGHT(DEC2HEX((AX11)/180*2^31),8)), " ") -> FFF22FC1
A12: ='CALIBRATION GUIDE'!B63 -> CH16=0.000A CH17=0.000A CH18=0.000A CH19=0.000A | D12: =D8+2 -> 29 | E12: 2 | G12: =MID(INDIRECT(ADDRESS(D12,1)),(E12-1)*19+1,3) -> 005 | H12: =TRIM(MID(INDIRECT(ADDRESS(D12,1)),(E12-1)*19+4,16)) -> PH_SRC_2_3 | I12: =TRIM(MID(INDIRECT(ADDRESS(D12+1,1)),(E12-1)*19+1,19)) -> 502 | J12: uQ32.0 | K12: =(HEX2DEC(LEFT(REPT("0",16-LEN(I12))&I12,10))*16^6+HEX2DEC(RIGHT(I12,6)))/2^(0+MID(J12,FIND(".",J12)+1,2)) -> 1282 | N12: =N8+2 -> 172 | O12: 2 | Q12: =MID(INDIRECT(ADDRESS(N12,1)),(O12-1)*19+1,3) -> 005 | R12: =TRIM(MID(INDIRECT(ADDRESS(N12,1)),(O12-1)*19+4,16)) -> CREEP_FLAG | S12: =TRIM(MID(INDIRECT(ADDRESS(N12+1,1)),(O12-1)*19+1,19)) -> 0 | T12: uQ32.0 | U12: =(HEX2DEC(LEFT(REPT("0",16-LEN(S12))&S12,10))*16^6+HEX2DEC(RIGHT(S12,6)))/2^(0+MID(T12,FIND(".",T12)+1,2)) -> 0 | X12: =X8+2 -> 235 | Y12: 2 | AA12: =MID(INDIRECT(ADDRESS(X12,1)),(Y12-1)*19+1,3) -> 005 | AB12: =TRIM(MID(INDIRECT(ADDRESS(X12,1)),(Y12-1)*19+4,16)) -> CH5 | AC12: =TRIM(MID(INDIRECT(ADDRESS(X12+1,1)),(Y12-1)*19+1,19)) -> 9C6F3742EA8 | AD12: uQ24.40 | AE12: =(HEX2DEC(LEFT(REPT("0",16-LEN(AC12))&AC12,10))*16^6+HEX2DEC(RIGHT(AC12,6)))/2^(0+MID(AD12,FIND(".",AD12)+1,2)) -> 9.7771523 | AF12: =SQRT(AE12/$U$16)*K118 -> 30.518371 | AH12: ='CALIBRATION GUIDE'!B18 -> 5 | AI12: ='CALIBRATION GUIDE'!C18 -> I(CT) | AJ12: =IF('CALIBRATION GUIDE'!C18="V"," ", IF(ISNA(MATCH(AH12,CONFIGURATOR!$D$21:$D$51,0))=TRUE," ",MATCH(AH12,CONFIGURATOR!$D$21:$D$51,0)-1) ) -> 2 | AK12: {=IF(AJ12=" "," ",INDIRECT(ADDRESS(103+AJ12,31)))} -> 12.916565 | AL12: {=IF(AJ12=" "," ",INDIRECT(ADDRESS(135+AJ12,31)))} -> 22.308904 | AM12: =IF(AJ12=" ", " ", IF(OR(AK12=0,AL12=0),0, DEGREES(ATAN2(AK12,AL12)))) -> 59.929718 | AN12: =AF12 -> 30.518371 | AO12: ='CALIBRATION GUIDE'!D18 -> 30 | AP12: =K150 -> 1 | AQ12: =IF(AN12>0,AO12/AN12,1) -> 0.98301448 | AR12: =IF((AQ12*AP12)<4,AQ12*AP12,1) -> 0.98301448 | AS12: =1+AS11 -> 143 | AT12: =IF('CALIBRATION GUIDE'!E18="Y",RIGHT(DEC2HEX(INT(AR12*2^29+0.5),8),8)," ") -> 1F74DAC6 | AU12: =K182 -> 0 | AV12: =IF(AM12=" ",0,AM12-'CALIBRATION GUIDE'!$C$8) -> -0.070281943 | AW12: =IF(AV12=0, 0, AV12*60/'CALIBRATION GUIDE'!$C$7) -> -0.084338331 | AX12: =AW12+AU12 -> -0.084338331 | AY12: =1+AY11 -> 175 | AZ12: =IF('CALIBRATION GUIDE'!E18="Y",IF(AI12="V",0,RIGHT(DEC2HEX((AX12)/180*2^31),8)), " ") -> FFF0A58D
A13: ='CALIBRATION GUIDE'!B64 -> CH20=0.000A CH21=0.000A CH22=0.000A CH23=0.000A | D13: =D9+2 -> 29 | E13: 3 | G13: =MID(INDIRECT(ADDRESS(D13,1)),(E13-1)*19+1,3) -> 006 | H13: =TRIM(MID(INDIRECT(ADDRESS(D13,1)),(E13-1)*19+4,16)) -> PH_SRC_4_5 | I13: =TRIM(MID(INDIRECT(ADDRESS(D13+1,1)),(E13-1)*19+1,19)) -> 0 | J13: uQ32.0 | K13: =(HEX2DEC(LEFT(REPT("0",16-LEN(I13))&I13,10))*16^6+HEX2DEC(RIGHT(I13,6)))/2^(0+MID(J13,FIND(".",J13)+1,2)) -> 0 | N13: =N9+2 -> 172 | O13: 3 | Q13: =MID(INDIRECT(ADDRESS(N13,1)),(O13-1)*19+1,3) -> 006 | R13: =TRIM(MID(INDIRECT(ADDRESS(N13,1)),(O13-1)*19+4,16)) -> PH_ACTIVE_FLAG | S13: =TRIM(MID(INDIRECT(ADDRESS(N13+1,1)),(O13-1)*19+1,19)) -> 7 | T13: uQ32.0 | U13: =(HEX2DEC(LEFT(REPT("0",16-LEN(S13))&S13,10))*16^6+HEX2DEC(RIGHT(S13,6)))/2^(0+MID(T13,FIND(".",T13)+1,2)) -> 7 | X13: =X9+2 -> 235 | Y13: 3 | AA13: =MID(INDIRECT(ADDRESS(X13,1)),(Y13-1)*19+1,3) -> 006 | AB13: =TRIM(MID(INDIRECT(ADDRESS(X13,1)),(Y13-1)*19+4,16)) -> CH6 | AC13: =TRIM(MID(INDIRECT(ADDRESS(X13+1,1)),(Y13-1)*19+1,19)) -> 2705D | AD13: uQ24.40 | AE13: =(HEX2DEC(LEFT(REPT("0",16-LEN(AC13))&AC13,10))*16^6+HEX2DEC(RIGHT(AC13,6)))/2^(0+MID(AD13,FIND(".",AD13)+1,2)) -> 1.453709e-07 | AF13: =SQRT(AE13/$U$16)*K119 -> 0.0037212933 | AH13: ='CALIBRATION GUIDE'!B19 -> 6 | AI13: ='CALIBRATION GUIDE'!C19 -> I(CT) | AJ13: =IF('CALIBRATION GUIDE'!C19="V"," ", IF(ISNA(MATCH(AH13,CONFIGURATOR!$D$21:$D$51,0))=TRUE," ",MATCH(AH13,CONFIGURATOR!$D$21:$D$51,0)-1) ) -> 3 | AK13: {=IF(AJ13=" "," ",INDIRECT(ADDRESS(103+AJ13,31)))} -> 0 | AL13: {=IF(AJ13=" "," ",INDIRECT(ADDRESS(135+AJ13,31)))} -> 0 | AM13: =IF(AJ13=" ", " ", IF(OR(AK13=0,AL13=0),0, DEGREES(ATAN2(AK13,AL13)))) -> 0 | AN13: =AF13 -> 0.0037212933 | AO13: ='CALIBRATION GUIDE'!D19 -> 30 | AP13: =K151 -> 1 | AQ13: =IF(AN13>0,AO13/AN13,1) -> 8061.7134 | AR13: =IF((AQ13*AP13)<4,AQ13*AP13,1) -> 1 | AS13: =1+AS12 -> 144 | AT13: =IF('CALIBRATION GUIDE'!E19="Y",RIGHT(DEC2HEX(INT(AR13*2^29+0.5),8),8)," ") | AU13: =K183 -> 0 | AV13: =IF(AM13=" ",0,AM13-'CALIBRATION GUIDE'!$C$8) -> -60 | AW13: =IF(AV13=0, 0, AV13*60/'CALIBRATION GUIDE'!$C$7) -> -72 | AX13: =AW13+AU13 -> -72 | AY13: =1+AY12 -> 176 | AZ13: =IF('CALIBRATION GUIDE'!E19="Y",IF(AI13="V",0,RIGHT(DEC2HEX((AX13)/180*2^31),8)), " ")
A14: ='CALIBRATION GUIDE'!B65 -> CH24=0.000A CH25=0.000A CH26=0.000A CH27=0.000A | D14: =D10+2 -> 29 | E14: 4 | G14: =MID(INDIRECT(ADDRESS(D14,1)),(E14-1)*19+1,3) -> 007 | H14: =TRIM(MID(INDIRECT(ADDRESS(D14,1)),(E14-1)*19+4,16)) -> PH_SRC_6_7 | I14: =TRIM(MID(INDIRECT(ADDRESS(D14+1,1)),(E14-1)*19+1,19)) -> 0 | J14: uQ32.0 | K14: =(HEX2DEC(LEFT(REPT("0",16-LEN(I14))&I14,10))*16^6+HEX2DEC(RIGHT(I14,6)))/2^(0+MID(J14,FIND(".",J14)+1,2)) -> 0 | N14: =N10+2 -> 172 | O14: 4 | Q14: =MID(INDIRECT(ADDRESS(N14,1)),(O14-1)*19+1,3) -> 007 | R14: =TRIM(MID(INDIRECT(ADDRESS(N14,1)),(O14-1)*19+4,16)) -> CAPTURE_STATUS | S14: =TRIM(MID(INDIRECT(ADDRESS(N14+1,1)),(O14-1)*19+1,19)) -> 0 | T14: uQ32.0 | U14: =(HEX2DEC(LEFT(REPT("0",16-LEN(S14))&S14,10))*16^6+HEX2DEC(RIGHT(S14,6)))/2^(0+MID(T14,FIND(".",T14)+1,2)) -> 0 | X14: =X10+2 -> 235 | Y14: 4 | AA14: =MID(INDIRECT(ADDRESS(X14,1)),(Y14-1)*19+1,3) -> 007 | AB14: =TRIM(MID(INDIRECT(ADDRESS(X14,1)),(Y14-1)*19+4,16)) -> CH7 | AC14: =TRIM(MID(INDIRECT(ADDRESS(X14+1,1)),(Y14-1)*19+1,19)) -> 22FB8 | AD14: uQ24.40 | AE14: =(HEX2DEC(LEFT(REPT("0",16-LEN(AC14))&AC14,10))*16^6+HEX2DEC(RIGHT(AC14,6)))/2^(0+MID(AD14,FIND(".",AD14)+1,2)) -> 1.3031968e-07 | AF14: =SQRT(AE14/$U$16)*K120 -> 0.0094237135 | AH14: ='CALIBRATION GUIDE'!B20 -> 7 | AI14: ='CALIBRATION GUIDE'!C20 -> I(CT) | AJ14: =IF('CALIBRATION GUIDE'!C20="V"," ", IF(ISNA(MATCH(AH14,CONFIGURATOR!$D$21:$D$51,0))=TRUE," ",MATCH(AH14,CONFIGURATOR!$D$21:$D$51,0)-1) ) -> 4 | AK14: {=IF(AJ14=" "," ",INDIRECT(ADDRESS(103+AJ14,31)))} -> 0 | AL14: {=IF(AJ14=" "," ",INDIRECT(ADDRESS(135+AJ14,31)))} -> 0 | AM14: =IF(AJ14=" ", " ", IF(OR(AK14=0,AL14=0),0, DEGREES(ATAN2(AK14,AL14)))) -> 0 | AN14: =AF14 -> 0.0094237135 | AO14: ='CALIBRATION GUIDE'!D20 -> 30 | AP14: =K152 -> 1 | AQ14: =IF(AN14>0,AO14/AN14,1) -> 3183.4584 | AR14: =IF((AQ14*AP14)<4,AQ14*AP14,1) -> 1 | AS14: =1+AS13 -> 145 | AT14: =IF('CALIBRATION GUIDE'!E20="Y",RIGHT(DEC2HEX(INT(AR14*2^29+0.5),8),8)," ") | AU14: =K184 -> 0 | AV14: =IF(AM14=" ",0,AM14-'CALIBRATION GUIDE'!$C$8) -> -60 | AW14: =IF(AV14=0, 0, AV14*60/'CALIBRATION GUIDE'!$C$7) -> -72 | AX14: =AW14+AU14 -> -72 | AY14: =1+AY13 -> 177 | AZ14: =IF('CALIBRATION GUIDE'!E20="Y",IF(AI14="V",0,RIGHT(DEC2HEX((AX14)/180*2^31),8)), " ")
A15: ='CALIBRATION GUIDE'!B66 -> CH28=0.000A CH29=0.000A CH30=0.000A CH31=0.000A | D15: =D11+2 -> 31 | E15: 1 | G15: =MID(INDIRECT(ADDRESS(D15,1)),(E15-1)*19+1,3) -> 008 | H15: =TRIM(MID(INDIRECT(ADDRESS(D15,1)),(E15-1)*19+4,16)) -> PH_SRC_8_9 | I15: =TRIM(MID(INDIRECT(ADDRESS(D15+1,1)),(E15-1)*19+1,19)) -> 0 | J15: uQ32.0 | K15: =(HEX2DEC(LEFT(REPT("0",16-LEN(I15))&I15,10))*16^6+HEX2DEC(RIGHT(I15,6)))/2^(0+MID(J15,FIND(".",J15)+1,2)) -> 0 | N15: =N11+2 -> 174 | O15: 1 | Q15: =MID(INDIRECT(ADDRESS(N15,1)),(O15-1)*19+1,3) -> 008 | R15: =TRIM(MID(INDIRECT(ADDRESS(N15,1)),(O15-1)*19+4,16)) -> INTERVAL_NUM | S15: =TRIM(MID(INDIRECT(ADDRESS(N15+1,1)),(O15-1)*19+1,19)) -> 3D60015 | T15: uQ32.0 | U15: =(HEX2DEC(LEFT(REPT("0",16-LEN(S15))&S15,10))*16^6+HEX2DEC(RIGHT(S15,6)))/2^(0+MID(T15,FIND(".",T15)+1,2)) -> 64356373 | X15: =X11+2 -> 237 | Y15: 1 | AA15: =MID(INDIRECT(ADDRESS(X15,1)),(Y15-1)*19+1,3) -> 008 | AB15: =TRIM(MID(INDIRECT(ADDRESS(X15,1)),(Y15-1)*19+4,16)) -> CH8 | AC15: =TRIM(MID(INDIRECT(ADDRESS(X15+1,1)),(Y15-1)*19+1,19)) -> 0 | AD15: uQ24.40 | AE15: =(HEX2DEC(LEFT(REPT("0",16-LEN(AC15))&AC15,10))*16^6+HEX2DEC(RIGHT(AC15,6)))/2^(0+MID(AD15,FIND(".",AD15)+1,2)) -> 0 | AF15: =SQRT(AE15/$U$16)*K121 -> 0 | AH15: ='CALIBRATION GUIDE'!B21 -> 8 | AI15: ='CALIBRATION GUIDE'!C21 -> I(CT) | AJ15: =IF('CALIBRATION GUIDE'!C21="V"," ", IF(ISNA(MATCH(AH15,CONFIGURATOR!$D$21:$D$51,0))=TRUE," ",MATCH(AH15,CONFIGURATOR!$D$21:$D$51,0)-1) ) -> 5 | AK15: {=IF(AJ15=" "," ",INDIRECT(ADDRESS(103+AJ15,31)))} -> 0 | AL15: {=IF(AJ15=" "," ",INDIRECT(ADDRESS(135+AJ15,31)))} -> 0 | AM15: =IF(AJ15=" ", " ", IF(OR(AK15=0,AL15=0),0, DEGREES(ATAN2(AK15,AL15)))) -> 0 | AN15: =AF15 -> 0 | AO15: ='CALIBRATION GUIDE'!D21 -> 30 | AP15: =K153 -> 1 | AQ15: =IF(AN15>0,AO15/AN15,1) -> 1 | AR15: =IF((AQ15*AP15)<4,AQ15*AP15,1) -> 1 | AS15: =1+AS14 -> 146 | AT15: =IF('CALIBRATION GUIDE'!E21="Y",RIGHT(DEC2HEX(INT(AR15*2^29+0.5),8),8)," ") | AU15: =K185 -> 0 | AV15: =IF(AM15=" ",0,AM15-'CALIBRATION GUIDE'!$C$8) -> -60 | AW15: =IF(AV15=0, 0, AV15*60/'CALIBRATION GUIDE'!$C$7) -> -72 | AX15: =AW15+AU15 -> -72 | AY15: =1+AY14 -> 178 | AZ15: =IF('CALIBRATION GUIDE'!E21="Y",IF(AI15="V",0,RIGHT(DEC2HEX((AX15)/180*2^31),8)), " ")
